Workbook
Name ListaCargosStd: Precios!$B$2:$B$1023
Name ListaLocales: Locales!$A$2:$A$110
Name ListaMateriales: Precios!$C$2:$C$1023
Name TablaLocales: Locales!$A$1:$B$110
Name TablaMapeoCargos: MapeoCargos!$A$2:$B$1001

Sheet Locales
A1: LOCAL | B1: GRUPO
A2: SAN BORJA | B2: LIMA E ICA PROVINCIA
A3: POLO | B3: LIMA E ICA PROVINCIA
A4: JESUS MARIA | B4: LIMA E ICA PROVINCIA
A5: DOÑA ROSA | B5: LIMA E ICA PROVINCIA
A6: SURCO | B6: LIMA E ICA PROVINCIA
A7: ICA | B7: LIMA E ICA PROVINCIA
A8: ICA PROVINCIA | B8: LIMA E ICA PROVINCIA
A9: DOMINICANA | B9: LIMA E ICA PROVINCIA
A10: LIMA HISTORICO | B10: LIMA E ICA PROVINCIA
A11: FAUCETT | B11: LIMA E ICA PROVINCIA
A12: ALAMEDA | B12: LIMA E ICA PROVINCIA
... A37: SAN ISIDRO | B37: VILLA STEAKHOUSE

Sheet MapeoCargos
A1: CARGO ORIGINAL (del listado) | B1: CARGO ESTANDAR (para precio/uniforme)
A2: MOZO | B2: MOZO
A3: MOZO P/T | B3: MOZO
A4: ENTRENADOR DE SERVICIO | B4: MOZO
A5: MOZO PART TIME | B5: MOZO
A6: AZAFATA | B6: AZAFATA
A7: AZAFATA P/T | B7: AZAFATA
A8: AZAFATA FULL TIME | B8: AZAFATA
A9: PACKER | B9: PACKER
A10: PACKER P/T | B10: PACKER
A11: MOTORIZADO | B11: MOTORIZADO
A12: MOTORIZADO P/T | B12: MOTORIZADO
... A91: COCINERO(A) SALTEADOR | B91: PRODUCCIÓN / COCINA

Sheet Personal
A1: DNI | B1: RAZON SOCIAL | C1: LOCAL | D1: APELLIDOS Y NOMBRES | E1: CARGO ORIGINAL | F1: CARGO ESTANDAR (auto) | G1: FECHA INGRESO | I1: LISTADO DE PERSONAL
A2: 09739137 | B2: VILLA CHICKEN S.A.C. | C2: VCH-ADM | D2: MELGAREJO MEZA ZENOVIO | E2: GERENTE DE OPERACIONES | F2: {=IFERROR(_xlfn.XLOOKUP(E2,MapeoCargos!$A:$A,MapeoCargos!$B:$B,E2),E2)} -> GERENTE DE OPERACIONES | G2: 38842
A3: 28108075 | B3: VILLA CHICKEN S.A.C. | C3: SURCO | D3: FLORES TUCTO SEGUNDO ANDRES | E3: AYUDANTE DE COCINA | F3: {=IFERROR(_xlfn.XLOOKUP(E3,MapeoCargos!$A:$A,MapeoCargos!$B:$B,E3),E3)} -> PRODUCCIÓN / COCINA | G3: 38930
A4: 27559471 | B4: VILLA CHICKEN S.A.C. | C4: SAN BORJA | D4: GUEVARA SILVA JUAN ANIBAL | E4: ADMINISTRADOR(A) | F4: {=IFERROR(_xlfn.XLOOKUP(E4,MapeoCargos!$A:$A,MapeoCargos!$B:$B,E4),E4)} -> STAFF ADMINISTRATIVO | G4: 40026
A5: 40564075 | B5: VILLA CHICKEN S.A.C. | C5: SAN BORJA | D5: LLAMO FERNANDEZ RAMIRO | E5: MOZO | F5: {=IFERROR(_xlfn.XLOOKUP(E5,MapeoCargos!$A:$A,MapeoCargos!$B:$B,E5),E5)} -> MOZO | G5: 40253
A6: 06819776 | B6: VILLA CHICKEN S.A.C. | C6: SAN BORJA | D6: CALDERON ROJAS LEODORO | E6: MOZO | F6: {=IFERROR(_xlfn.XLOOKUP(E6,MapeoCargos!$A:$A,MapeoCargos!$B:$B,E6),E6)} -> MOZO | G6: 40269
A7: 09282806 | B7: VILLA INVEST S.A.C. | C7: VI-ADM | D7: PALIZA BAYLON VICENTE PAUL | E7: SUPERVISOR DE PRODUCCION | F7: {=IFERROR(_xlfn.XLOOKUP(E7,MapeoCargos!$A:$A,MapeoCargos!$B:$B,E7),E7)} -> SUPERVISOR DE PRODUCCION | G7: 40422
A8: 42210873 | B8: VILLA INVEST S.A.C. | C8: EJERCITO | D8: NEYRA RODRIGUEZ DANNY IVAN | E8: HORNERO (A) | F8: {=IFERROR(_xlfn.XLOOKUP(E8,MapeoCargos!$A:$A,MapeoCargos!$B:$B,E8),E8)} -> PRODUCCIÓN / COCINA | G8: 40749
A9: 06446881 | B9: VILLA CHICKEN S.A.C. | C9: VCH-ADM | D9: GOMEZ RIOS ELENA | E9: JEFE DE RECURSOS HUMANOS 2 | F9: {=IFERROR(_xlfn.XLOOKUP(E9,MapeoCargos!$A:$A,MapeoCargos!$B:$B,E9),E9)} -> JEFE DE RECURSOS HUMANOS 2 | G9: 40756
A10: 40706652 | B10: VILLA CHICKEN S.A.C. | C10: SAN BORJA | D10: DIAZ CCALA HUGO | E10: HORNERO (A) | F10: {=IFERROR(_xlfn.XLOOKUP(E10,MapeoCargos!$A:$A,MapeoCargos!$B:$B,E10),E10)} -> PRODUCCIÓN / COCINA | G10: 40969
A11: 06102961 | B11: VILLA INVEST S.A.C. | C11: VI-ADM | D11: CHIN CHAU ROSA | E11: GERENTE GENERAL | F11: {=IFERROR(_xlfn.XLOOKUP(E11,MapeoCargos!$A:$A,MapeoCargos!$B:$B,E11),E11)} -> GERENTE GENERAL | G11: 41031
A12: 48037304 | B12: VILLA INVEST S.A.C. | C12: OLIVOS | D12: ROJAS BAYONA BERUSKA TAMARA | E12: ADMINISTRADOR(A) | F12: {=IFERROR(_xlfn.XLOOKUP(E12,MapeoCargos!$A:$A,MapeoCargos!$B:$B,E12),E12)} -> STAFF ADMINISTRATIVO | G12: 41061
A13: 07783723 | B13: VILLA CHICKEN S.A.C. | C13: VCH-ADM | D13: LAU PEREZ ALFREDO JOSE | E13: ASISTENTE DE GERENCIA | F13: {=IFERROR(_xlfn.XLOOKUP(E13,MapeoCargos!$A:$A,MapeoCargos!$B:$B,E13),E13)} -> ASISTENTE DE GERENCIA | G13: 41061
... A73: 47967370 | B73: VILLA INVEST S.A.C. | C73: SAN MIGUEL | D73: CUTIPA PALOMINO JOSUE ROBERTO | E73: MOTORIZADO | F73: {=IFERROR(_xlfn.XLOOKUP(E73,MapeoCargos!$A:$A,MapeoCargos!$B:$B,E73),E73)} -> MOTORIZADO | G73: 42826
A74: 72511903 | B74: VILLA INVEST S.A.C. | C74: EJERCITO | D74: PANANA NAJARRO LUIS ENRIQUE | E74: MOTORIZADO | F74: {=IFERROR(_xlfn.XLOOKUP(E74,MapeoCargos!$A:$A,MapeoCargos!$B:$B,E74),E74)} -> MOTORIZADO | G74: 45901 | H74: AGREGADO DEL LISTADO DE PERSONAL DE OCTUBRE
A75: 45728123 | B75: VILLA CHICKEN S.A.C. | C75: SAN BORJA | D75: DIAZ ESTELA ENRIQUE | E75: MOTORIZADO | F75: {=IFERROR(_xlfn.XLOOKUP(E75,MapeoCargos!$A:$A,MapeoCargos!$B:$B,E75),E75)} -> MOTORIZADO | G75: 42826
A76: 47247086 | B76: VILLA CHICKEN S.A.C. | C76: VCH-ADM | D76: PINEDO JULCA GEINER OMAR | E76: SUPERVISOR DE OPERACIONES | F76: {=IFERROR(_xlfn.XLOOKUP(E76,MapeoCargos!$A:$A,MapeoCargos!$B:$B,E76),E76)} -> SUPERVISOR DE OPERACIONES | G76: 42856
A77: 44449260 | B77: VILLA CHICKEN S.A.C. | C77: ICA | D77: ARELLANO MUÑOZ GEORGE JOEL | E77: HORNERO (A) | F77: {=IFERROR(_xlfn.XLOOKUP(E77,MapeoCargos!$A:$A,MapeoCargos!$B:$B,E77),E77)} -> PRODUCCIÓN / COCINA | G77: 42856
A78: 41185109 | B78: FOOD & BEVERAGE INVEST S.A.C. | C78: HACIENDA | D78: QUIROZ CAPCHA MAXIMO | E78: PARRILLERO (A) | F78: {=IFERROR(_xlfn.XLOOKUP(E78,MapeoCargos!$A:$A,MapeoCargos!$B:$B,E78),E78)} -> PRODUCCIÓN / COCINA | G78: 42887
A79: 43965735 | B79: VILLA CHICKEN S.A.C. | C79: ICA | D79: LEVANO TASAYCO ROBERTO JAVIER | E79: HORNERO (A) | F79: {=IFERROR(_xlfn.XLOOKUP(E79,MapeoCargos!$A:$A,MapeoCargos!$B:$B,E79),E79)} -> PRODUCCIÓN / COCINA | G79: 42887
A80: 09491742 | B80: VILLA CHICKEN S.A.C. | C80: SURCO | D80: VILLAR RAMOS JOSE ANTONIO | E80: ADMINISTRADOR(A) | F80: {=IFERROR(_xlfn.XLOOKUP(E80,MapeoCargos!$A:$A,MapeoCargos!$B:$B,E80),E80)} -> STAFF ADMINISTRATIVO | G80: 42902
A81: 45038734 | B81: VILLA CHICKEN S.A.C. | C81: POLO | D81: PEZO LOPEZ SOFIA ISABEL | E81: CAJERO (A) | F81: {=IFERROR(_xlfn.XLOOKUP(E81,MapeoCargos!$A:$A,MapeoCargos!$B:$B,E81),E81)} -> CAJA | G81: 42917
A82: 43191410 | B82: FOOD & BEVERAGE INVEST S.A.C. | C82: MAGDALENA | D82: CAJUSOL SANJINEZ WILLY FRANKLIN | E82: PARRILLERO (A) | F82: {=IFERROR(_xlfn.XLOOKUP(E82,MapeoCargos!$A:$A,MapeoCargos!$B:$B,E82),E82)} -> PRODUCCIÓN / COCINA | G82: 42963
A83: 07538742 | B83: VILLA CHICKEN S.A.C. | C83: POLO | D83: HUAMANI SACSI MARIA LUISA | E83: AUXILIAR DE LIMPIEZA | F83: {=IFERROR(_xlfn.XLOOKUP(E83,MapeoCargos!$A:$A,MapeoCargos!$B:$B,E83),E83)} -> LIMPIEZA / MANTENIMIENTO | G83: 43009
A84: 49097756 | B84: FOOD & BEVERAGE INVEST S.A.C. | C84: F&B-ADM | D84: SIMANCA REYES JOSE ALEJANDRO | E84: COORDINADOR DE MANTENIMIENTO | F84: {=IFERROR(_xlfn.XLOOKUP(E84,MapeoCargos!$A:$A,MapeoCargos!$B:$B,E84),E84)} -> COORDINADOR DE MANTENIMIENTO | G84: 43032
A85: 49003395 | B85: FOOD & BEVERAGE INVEST S.A.C. | C85: F&B-ADM | D85: KONG BARRIOS DANIELA ROSA | E85: COMMUNITY MANAGER | F85: {=IFERROR(_xlfn.XLOOKUP(E85,MapeoCargos!$A:$A,MapeoCargos!$B:$B,E85),E85)} -> COMMUNITY MANAGER | G85: 43032
A86: 41855846 | B86: VILLA CHICKEN S.A.C. | C86: SAN BORJA | D86: VILCA ROJAS PEDRO YULIO | E86: MOTORIZADO | F86: {=IFERROR(_xlfn.XLOOKUP(E86,MapeoCargos!$A:$A,MapeoCargos!$B:$B,E86),E86)} -> MOTORIZADO | G86: 43040
... A375: 72896244 | B375: VILLA INVEST S.A.C. | C375: OLIVOS | D375: YUCRA SANTOS GABRIEL EDUARDO | E375: AUXILIAR DE LIMPIEZA | F375: {=IFERROR(_xlfn.XLOOKUP(E375,MapeoCargos!$A:$A,MapeoCargos!$B:$B,E375),E375)} -> LIMPIEZA / MANTENIMIENTO | G375: 45170
A376: 46722628 | B376: VILLA INVEST S.A.C. | C376: LARCOMAR | D376: REYES RAMIREZ DIANA YOLI | E376: ADMINISTRADOR(A) JUNIOR | F376: {=IFERROR(_xlfn.XLOOKUP(E376,MapeoCargos!$A:$A,MapeoCargos!$B:$B,E376),E376)} -> STAFF ADMINISTRATIVO | G376: 45170 | H376: SALE COMO CAJERO EN EL LISTADO DE PERSONAL
A377: 10882142 | B377: VILLA CHICKEN S.A.C. | C377: JESUS MARIA | D377: GRANADOS MORA JENNY MERCEDES | E377: AUXILIAR DE LIMPIEZA | F377: {=IFERROR(_xlfn.XLOOKUP(E377,MapeoCargos!$A:$A,MapeoCargos!$B:$B,E377),E377)} -> LIMPIEZA / MANTENIMIENTO | G377: 45181
A378: 45983609 | B378: VILLA INVEST S.A.C. | C378: NAVARRETE | D378: ANICAMA PIÑA RUFFO ENRIQUE | E378: CAJERO (A) | F378: {=IFERROR(_xlfn.XLOOKUP(E378,MapeoCargos!$A:$A,MapeoCargos!$B:$B,E378),E378)} -> CAJA | G378: 45181
A379: 47726715 | B379: VILLA CHICKEN S.A.C. | C379: HISTORICO | D379: LACHOS RIVERA JOSE MANUEL | E379: SEGURIDAD | F379: {=IFERROR(_xlfn.XLOOKUP(E379,MapeoCargos!$A:$A,MapeoCargos!$B:$B,E379),E379)} -> SEGURIDAD | G379: 45181
A380: 46007144 | B380: VILLA CHICKEN S.A.C. | C380: VCH-ADM | D380: CARPIO FERREYRA JERICO ANDRES | E380: GERENTE DE MARKETING | F380: {=IFERROR(_xlfn.XLOOKUP(E380,MapeoCargos!$A:$A,MapeoCargos!$B:$B,E380),E380)} -> GERENTE DE MARKETING | G380: 45187
A381: 44265083 | B381: VILLA CHICKEN S.A.C. | C381: SURCO | D381: IZUISA PEREZ KERVIN | E381: HORNERO (A) | F381: {=IFERROR(_xlfn.XLOOKUP(E381,MapeoCargos!$A:$A,MapeoCargos!$B:$B,E381),E381)} -> PRODUCCIÓN / COCINA | G381: 45195
A382: 47008833 | B382: VILLA CHICKEN S.A.C. | C382: ICA | D382: VARGAS FERNANDEZ JAHIR ALESSANDRO | E382: ADMINISTRADOR(A) | F382: {=IFERROR(_xlfn.XLOOKUP(E382,MapeoCargos!$A:$A,MapeoCargos!$B:$B,E382),E382)} -> STAFF ADMINISTRATIVO | G382: 45200
A383: 74530037 | B383: VILLA CHICKEN S.A.C. | C383: SURCO | D383: REGALADO BELLIDO MICAL ZOE | E383: AZAFATA | F383: {=IFERROR(_xlfn.XLOOKUP(E383,MapeoCargos!$A:$A,MapeoCargos!$B:$B,E383),E383)} -> AZAFATA | G383: 45202
A384: 72196501 | B384: VILLA CHICKEN S.A.C. | C384: HISTORICO | D384: MARTINEZ OSORES LUIS ENRIQUE | E384: MOZO P/T | F384: {=IFERROR(_xlfn.XLOOKUP(E384,MapeoCargos!$A:$A,MapeoCargos!$B:$B,E384),E384)} -> MOZO | G384: 45202
A385: 74713457 | B385: FOOD & BEVERAGE INVEST S.A.C. | C385: F&B-CALL | D385: ASIAN ÑAUPA MAYRA BELEN | E385: TELEOPERADOR (A) P/T | F385: {=IFERROR(_xlfn.XLOOKUP(E385,MapeoCargos!$A:$A,MapeoCargos!$B:$B,E385),E385)} -> TELEOPERADOR (A) P/T | G385: 45209
A386: 42500135 | B386: FOOD & BEVERAGE INVEST S.A.C. | C386: F&B-CALL | D386: GUTIERREZ SALCEDO NOELIA JAZMIN | E386: TELEOPERADOR (A) P/T | F386: {=IFERROR(_xlfn.XLOOKUP(E386,MapeoCargos!$A:$A,MapeoCargos!$B:$B,E386),E386)} -> TELEOPERADOR (A) P/T | G386: 45209
A387: 72021148 | B387: FOOD & BEVERAGE INVEST S.A.C. | C387: F&B-ADM | D387: HURTADO FALCON LENIN ROSSELL | E387: AUDITOR DE CALIDAD | F387: {=IFERROR(_xlfn.XLOOKUP(E387,MapeoCargos!$A:$A,MapeoCargos!$B:$B,E387),E387)} -> AUDITOR DE CALIDAD | G387: 45223
...

Sheet Precios
A1: GRUPO | B1: CARGO ESTANDAR | C1: MATERIAL | D1: PRECIO (S,M,L) | E1: PRECIO (XL) | F1: PRECIO (XXL) | G1: CLAVE
A2: LIMA E ICA PROVINCIA | B2: MOTORIZADO | C2: POLO PIQUÉ PLOMO, MANGA LARGA MOTORIZADO | D2: =34/2 -> 17 | E2: =34/2 -> 17 | F2: =34/2 -> 17 | G2: =IF( OR(A2="",B2="",C2=""), "", CLEAN(TRIM(A2)) & "|" & CLEAN(TRIM(B2)) & "|" & CLEAN(TRIM(C2)) ) -> LIMA E ICA PROVINCIA|MOTORIZADO|POLO PIQUÉ PLOMO, MANGA LARGA MOTORIZADO
A3: LIMA E ICA PROVINCIA | B3: MOTORIZADO | C3: GORRO NEGRO MOTORIZADO | D3: =10/2 -> 5 | E3: =10/2 -> 5 | F3: =10/2 -> 5 | G3: =IF( OR(A3="",B3="",C3=""), "", CLEAN(TRIM(A3)) & "|" & CLEAN(TRIM(B3)) & "|" & CLEAN(TRIM(C3)) ) -> LIMA E ICA PROVINCIA|MOTORIZADO|GORRO NEGRO MOTORIZADO
A4: LIMA E ICA PROVINCIA | B4: MOTORIZADO | C4: CASACA NEGRA CON REFLECTIVOS MOTORIZADO | D4: 39 | E4: 39 | F4: 41 | G4: =IF( OR(A4="",B4="",C4=""), "", CLEAN(TRIM(A4)) & "|" & CLEAN(TRIM(B4)) & "|" & CLEAN(TRIM(C4)) ) -> LIMA E ICA PROVINCIA|MOTORIZADO|CASACA NEGRA CON REFLECTIVOS MOTORIZADO
A5: LIMA E ICA PROVINCIA | B5: PACKER | C5: POLO PIQUÉ PLOMO, MANGA LARGA PACKER | D5: =34/2 -> 17 | E5: =34/2 -> 17 | F5: =36/2 -> 18 | G5: =IF( OR(A5="",B5="",C5=""), "", CLEAN(TRIM(A5)) & "|" & CLEAN(TRIM(B5)) & "|" & CLEAN(TRIM(C5)) ) -> LIMA E ICA PROVINCIA|PACKER|POLO PIQUÉ PLOMO, MANGA LARGA PACKER
A6: LIMA E ICA PROVINCIA | B6: PACKER | C6: GORRO NEGRO PACKER | D6: =10/2 -> 5 | E6: =10/2 -> 5 | F6: =10/2 -> 5 | G6: =IF( OR(A6="",B6="",C6=""), "", CLEAN(TRIM(A6)) & "|" & CLEAN(TRIM(B6)) & "|" & CLEAN(TRIM(C6)) ) -> LIMA E ICA PROVINCIA|PACKER|GORRO NEGRO PACKER
A7: LIMA E ICA PROVINCIA | B7: PACKER | C7: CASACA NEGRA CON REFLECTIVOS PACKER | D7: 39 | E7: 39 | F7: 41 | G7: =IF( OR(A7="",B7="",C7=""), "", CLEAN(TRIM(A7)) & "|" & CLEAN(TRIM(B7)) & "|" & CLEAN(TRIM(C7)) ) -> LIMA E ICA PROVINCIA|PACKER|CASACA NEGRA CON REFLECTIVOS PACKER
A8: LIMA E ICA PROVINCIA | B8: STAFF ADMINISTRATIVO | C8: CAMISA OXFORD CELESTE | D8: =36/2 -> 18 | E8: =36/2 -> 18 | F8: =38/2 -> 19 | G8: =IF( OR(A8="",B8="",C8=""), "", CLEAN(TRIM(A8)) & "|" & CLEAN(TRIM(B8)) & "|" & CLEAN(TRIM(C8)) ) -> LIMA E ICA PROVINCIA|STAFF ADMINISTRATIVO|CAMISA OXFORD CELESTE
A9: LIMA E ICA PROVINCIA | B9: STAFF ADMINISTRATIVO | C9: SACO NEGRO ADM HOMBRE | D9: 60 | E9: 60 | F9: 62.5 | G9: =IF( OR(A9="",B9="",C9=""), "", CLEAN(TRIM(A9)) & "|" & CLEAN(TRIM(B9)) & "|" & CLEAN(TRIM(C9)) ) -> LIMA E ICA PROVINCIA|STAFF ADMINISTRATIVO|SACO NEGRO ADM HOMBRE
A10: LIMA E ICA PROVINCIA | B10: STAFF ADMINISTRATIVO | C10: POLO PIQUÉ PIZARRA RX, MANGA CORTA ADM | D10: =27/2 -> 13.5 | E10: =27/2 -> 13.5 | F10: =30/2 -> 15 | G10: =IF( OR(A10="",B10="",C10=""), "", CLEAN(TRIM(A10)) & "|" & CLEAN(TRIM(B10)) & "|" & CLEAN(TRIM(C10)) ) -> LIMA E ICA PROVINCIA|STAFF ADMINISTRATIVO|POLO PIQUÉ PIZARRA RX, MANGA CORTA ADM
A11: LIMA E ICA PROVINCIA | B11: STAFF ADMINISTRATIVO | C11: BLUSA OXFORD CELESTE | D11: =36/2 -> 18 | E11: =36/2 -> 18 | F11: =38/2 -> 19 | G11: =IF( OR(A11="",B11="",C11=""), "", CLEAN(TRIM(A11)) & "|" & CLEAN(TRIM(B11)) & "|" & CLEAN(TRIM(C11)) ) -> LIMA E ICA PROVINCIA|STAFF ADMINISTRATIVO|BLUSA OXFORD CELESTE
A12: LIMA E ICA PROVINCIA | B12: STAFF ADMINISTRATIVO | C12: SACO NEGRO ADM MUJER | D12: 35 | E12: 35 | F12: 37.5 | G12: =IF( OR(A12="",B12="",C12=""), "", CLEAN(TRIM(A12)) & "|" & CLEAN(TRIM(B12)) & "|" & CLEAN(TRIM(C12)) ) -> LIMA E ICA PROVINCIA|STAFF ADMINISTRATIVO|SACO NEGRO ADM MUJER
A13: LIMA E ICA PROVINCIA | B13: STAFF ADMINISTRATIVO | C13: POLO PIQUÉ PIZARRA RX, MANGA CORTA ADMI | D13: 15 | E13: 15 | F13: 16 | G13: =IF( OR(A13="",B13="",C13=""), "", CLEAN(TRIM(A13)) & "|" & CLEAN(TRIM(B13)) & "|" & CLEAN(TRIM(C13)) ) -> LIMA E ICA PROVINCIA|STAFF ADMINISTRATIVO|POLO PIQUÉ PIZARRA RX, MANGA CORTA ADMI
A14: LIMA E ICA PROVINCIA | B14: STAFF ADMINISTRATIVO | C14: CASACA ADM | D14: 39 | E14: 39 | F14: 41 | G14: =IF( OR(A14="",B14="",C14=""), "", CLEAN(TRIM(A14)) & "|" & CLEAN(TRIM(B14)) & "|" & CLEAN(TRIM(C14)) ) -> LIMA E ICA PROVINCIA|STAFF ADMINISTRATIVO|CASACA ADM
A15: LIMA E ICA PROVINCIA | B15: STAFF ADMINISTRATIVO | C15: PANTALÓN SAL Y PIMIENTA | D15: =22/2 -> 11 | E15: =22/2 -> 11 | F15: =23/2 -> 11.5 | G15: =IF( OR(A15="",B15="",C15=""), "", CLEAN(TRIM(A15)) & "|" & CLEAN(TRIM(B15)) & "|" & CLEAN(TRIM(C15)) ) -> LIMA E ICA PROVINCIA|STAFF ADMINISTRATIVO|PANTALÓN SAL Y PIMIENTA
A16: LIMA E ICA PROVINCIA | B16: STAFF ADMINISTRATIVO | C16: PECHERA GRIS EN DRILL | D16: =13/2 -> 6.5 | E16: =13/2 -> 6.5 | F16: =13/2 -> 6.5 | G16: =IF( OR(A16="",B16="",C16=""), "", CLEAN(TRIM(A16)) & "|" & CLEAN(TRIM(B16)) & "|" & CLEAN(TRIM(C16)) ) -> LIMA E ICA PROVINCIA|STAFF ADMINISTRATIVO|PECHERA GRIS EN DRILL
A17: LIMA E ICA PROVINCIA | B17: STAFF ADMINISTRATIVO | C17: GARIBALDI GRIS | D17: =9/2 -> 4.5 | E17: =9/2 -> 4.5 | F17: =9/2 -> 4.5 | G17: =IF( OR(A17="",B17="",C17=""), "", CLEAN(TRIM(A17)) & "|" & CLEAN(TRIM(B17)) & "|" & CLEAN(TRIM(C17)) ) -> LIMA E ICA PROVINCIA|STAFF ADMINISTRATIVO|GARIBALDI GRIS
A18: LIMA E ICA PROVINCIA | B18: STAFF ADMINISTRATIVO | C18: CHAQUETA DRILL BLANCO | D18: =32.5/2 -> 16.25 | E18: =32.5/2 -> 16.25 | F18: =34.5/2 -> 17.25 | G18: =IF( OR(A18="",B18="",C18=""), "", CLEAN(TRIM(A18)) & "|" & CLEAN(TRIM(B18)) & "|" & CLEAN(TRIM(C18)) ) -> LIMA E ICA PROVINCIA|STAFF ADMINISTRATIVO|CHAQUETA DRILL BLANCO
A19: LIMA E ICA PROVINCIA | B19: STAFF ADMINISTRATIVO | C19: POLO 30/1 GRIS | D19: =15/2 -> 7.5 | E19: =15/2 -> 7.5 | F19: =17/2 -> 8.5 | G19: =IF( OR(A19="",B19="",C19=""), "", CLEAN(TRIM(A19)) & "|" & CLEAN(TRIM(B19)) & "|" & CLEAN(TRIM(C19)) ) -> LIMA E ICA PROVINCIA|STAFF ADMINISTRATIVO|POLO 30/1 GRIS
A20: LIMA E ICA PROVINCIA | B20: STAFF ADMINISTRATIVO | C20: GORRO NEGRO ADM | D20: =10/2 -> 5 | E20: =10/2 -> 5 | F20: =10/2 -> 5 | G20: =IF( OR(A20="",B20="",C20=""), "", CLEAN(TRIM(A20)) & "|" & CLEAN(TRIM(B20)) & "|" & CLEAN(TRIM(C20)) ) -> LIMA E ICA PROVINCIA|STAFF ADMINISTRATIVO|GORRO NEGRO ADM
A21: LIMA E ICA PROVINCIA | B21: CAJA | C21: CAMISA A RALLAS AZUL | D21: =36/2 -> 18 | E21: =36/2 -> 18 | F21: =38/2 -> 19 | G21: =IF( OR(A21="",B21="",C21=""), "", CLEAN(TRIM(A21)) & "|" & CLEAN(TRIM(B21)) & "|" & CLEAN(TRIM(C21)) ) -> LIMA E ICA PROVINCIA|CAJA|CAMISA A RALLAS AZUL
A22: LIMA E ICA PROVINCIA | B22: CAJA | C22: PANTALÓN AZUL NOCHE | D22: =40/2 -> 20 | E22: =40/2 -> 20 | F22: =42/2 -> 21 | G22: =IF( OR(A22="",B22="",C22=""), "", CLEAN(TRIM(A22)) & "|" & CLEAN(TRIM(B22)) & "|" & CLEAN(TRIM(C22)) ) -> LIMA E ICA PROVINCIA|CAJA|PANTALÓN AZUL NOCHE
A23: LIMA E ICA PROVINCIA | B23: CAJA | C23: CHALECO AZUL NOCHE | D23: =35/2 -> 17.5 | E23: =35/2 -> 17.5 | F23: =37/2 -> 18.5 | G23: =IF( OR(A23="",B23="",C23=""), "", CLEAN(TRIM(A23)) & "|" & CLEAN(TRIM(B23)) & "|" & CLEAN(TRIM(C23)) ) -> LIMA E ICA PROVINCIA|CAJA|CHALECO AZUL NOCHE
A24: LIMA E ICA PROVINCIA | B24: CAJA | C24: SACO NEGRO CAJA HOMBRE | D24: 60 | E24: 60 | F24: 62.5 | G24: =IF( OR(A24="",B24="",C24=""), "", CLEAN(TRIM(A24)) & "|" & CLEAN(TRIM(B24)) & "|" & CLEAN(TRIM(C24)) ) -> LIMA E ICA PROVINCIA|CAJA|SACO NEGRO CAJA HOMBRE
A25: LIMA E ICA PROVINCIA | B25: CAJA | C25: BLUSA A RALLAS AZUL | D25: =36/2 -> 18 | E25: =36/2 -> 18 | F25: =38/2 -> 19 | G25: =IF( OR(A25="",B25="",C25=""), "", CLEAN(TRIM(A25)) & "|" & CLEAN(TRIM(B25)) & "|" & CLEAN(TRIM(C25)) ) -> LIMA E ICA PROVINCIA|CAJA|BLUSA A RALLAS AZUL
A26: LIMA E ICA PROVINCIA | B26: CAJA | C26: PANTALÓN AZUL NOCHE | D26: =40/2 -> 20 | E26: =40/2 -> 20 | F26: =42/2 -> 21 | G26: =IF( OR(A26="",B26="",C26=""), "", CLEAN(TRIM(A26)) & "|" & CLEAN(TRIM(B26)) & "|" & CLEAN(TRIM(C26)) ) -> LIMA E ICA PROVINCIA|CAJA|PANTALÓN AZUL NOCHE
A27: LIMA E ICA PROVINCIA | B27: CAJA | C27: CHALECO AZUL NOCHE | D27: =35/2 -> 17.5 | E27: =35/2 -> 17.5 | F27: =37/2 -> 18.5 | G27: =IF( OR(A27="",B27="",C27=""), "", CLEAN(TRIM(A27)) & "|" & CLEAN(TRIM(B27)) & "|" & CLEAN(TRIM(C27)) ) -> LIMA E ICA PROVINCIA|CAJA|CHALECO AZUL NOCHE
A28: LIMA E ICA PROVINCIA | B28: CAJA | C28: SACO NEGRO CAJA MUJER | D28: 35 | E28: 35 | F28: 37.5 | G28: =IF( OR(A28="",B28="",C28=""), "", CLEAN(TRIM(A28)) & "|" & CLEAN(TRIM(B28)) & "|" & CLEAN(TRIM(C28)) ) -> LIMA E ICA PROVINCIA|CAJA|SACO NEGRO CAJA MUJER
A29: LIMA E ICA PROVINCIA | B29: CAJA | C29: CASACA CAJA | D29: 39 | E29: 39 | F29: 41 | G29: =IF( OR(A29="",B29="",C29=""), "", CLEAN(TRIM(A29)) & "|" & CLEAN(TRIM(B29)) & "|" & CLEAN(TRIM(C29)) ) -> LIMA E ICA PROVINCIA|CAJA|CASACA CAJA
A30: LIMA E ICA PROVINCIA | B30: MOZO | C30: CAMISA BLANCA (MANGA LARGA) | D30: =37/2 -> 18.5 | E30: =37/2 -> 18.5 | F30: =39/2 -> 19.5 | G30: =IF( OR(A30="",B30="",C30=""), "", CLEAN(TRIM(A30)) & "|" & CLEAN(TRIM(B30)) & "|" & CLEAN(TRIM(C30)) ) -> LIMA E ICA PROVINCIA|MOZO|CAMISA BLANCA (MANGA LARGA)
A31: LIMA E ICA PROVINCIA | B31: MOZO | C31: MANDILON DRILL NEGRO | D31: =14/2 -> 7 | E31: =14/2 -> 7 | F31: =14/2 -> 7 | G31: =IF( OR(A31="",B31="",C31=""), "", CLEAN(TRIM(A31)) & "|" & CLEAN(TRIM(B31)) & "|" & CLEAN(TRIM(C31)) ) -> LIMA E ICA PROVINCIA|MOZO|MANDILON DRILL NEGRO
A32: LIMA E ICA PROVINCIA | B32: MOZO | C32: ANDARIN GRANATE | D32: =3.5/2 -> 1.75 | E32: =3.5/2 -> 1.75 | F32: =3.5/2 -> 1.75 | G32: =IF( OR(A32="",B32="",C32=""), "", CLEAN(TRIM(A32)) & "|" & CLEAN(TRIM(B32)) & "|" & CLEAN(TRIM(C32)) ) -> LIMA E ICA PROVINCIA|MOZO|ANDARIN GRANATE
A33: LIMA E ICA PROVINCIA | B33: MOZO | C33: POLO 31/1 GRIS | D33: 7.5 | E33: 7.5 | F33: 8.5 | G33: =IF( OR(A33="",B33="",C33=""), "", CLEAN(TRIM(A33)) & "|" & CLEAN(TRIM(B33)) & "|" & CLEAN(TRIM(C33)) ) -> LIMA E ICA PROVINCIA|MOZO|POLO 31/1 GRIS
A34: LIMA E ICA PROVINCIA | B34: MOZO | C34: CAMISA OXFORD CONCHE VINO | D34: =43/2 -> 21.5 | E34: =43/2 -> 21.5 | F34: =46/2 -> 23 | G34: =IF( OR(A34="",B34="",C34=""), "", CLEAN(TRIM(A34)) & "|" & CLEAN(TRIM(B34)) & "|" & CLEAN(TRIM(C34)) ) -> LIMA E ICA PROVINCIA|MOZO|CAMISA OXFORD CONCHE VINO
A35: LIMA E ICA PROVINCIA | B35: MOZO | C35: PECHERA NEGRA ENTRENADOR DE SERVICIO | D35: 12 | E35: 12 | F35: 12 | G35: =IF( OR(A35="",B35="",C35=""), "", CLEAN(TRIM(A35)) & "|" & CLEAN(TRIM(B35)) & "|" & CLEAN(TRIM(C35)) ) -> LIMA E ICA PROVINCIA|MOZO|PECHERA NEGRA ENTRENADOR DE SERVICIO
A36: LIMA E ICA PROVINCIA | B36: AZAFATA | C36: BLUSA BLANCA (MANGA LARGA) | D36: =37/2 -> 18.5 | E36: =37/2 -> 18.5 | F36: =39/2 -> 19.5 | G36: =IF( OR(A36="",B36="",C36=""), "", CLEAN(TRIM(A36)) & "|" & CLEAN(TRIM(B36)) & "|" & CLEAN(TRIM(C36)) ) -> LIMA E ICA PROVINCIA|AZAFATA|BLUSA BLANCA (MANGA LARGA)
A37: LIMA E ICA PROVINCIA | B37: AZAFATA | C37: MANDILON DRILL NEGRO | D37: =14/2 -> 7 | E37: =14/2 -> 7 | F37: =14/2 -> 7 | G37: =IF( OR(A37="",B37="",C37=""), "", CLEAN(TRIM(A37)) & "|" & CLEAN(TRIM(B37)) & "|" & CLEAN(TRIM(C37)) ) -> LIMA E ICA PROVINCIA|AZAFATA|MANDILON DRILL NEGRO
A38: LIMA E ICA PROVINCIA | B38: AZAFATA | C38: ANDARIN GRANATE | D38: =3.5/2 -> 1.75 | E38: =3.5/2 -> 1.75 | F38: =3.5/2 -> 1.75 | G38: =IF( OR(A38="",B38="",C38=""), "", CLEAN(TRIM(A38)) & "|" & CLEAN(TRIM(B38)) & "|" & CLEAN(TRIM(C38)) ) -> LIMA E ICA PROVINCIA|AZAFATA|ANDARIN GRANATE
A39: LIMA E ICA PROVINCIA | B39: SEGURIDAD | C39: CAMISA CHARCOL MANGA LARGA | D39: =36/2 -> 18 | E39: =36/2 -> 18 | F39: =38/2 -> 19 | G39: =IF( OR(A39="",B39="",C39=""), "", CLEAN(TRIM(A39)) & "|" & CLEAN(TRIM(B39)) & "|" & CLEAN(TRIM(C39)) ) -> LIMA E ICA PROVINCIA|SEGURIDAD|CAMISA CHARCOL MANGA LARGA
A40: LIMA E ICA PROVINCIA | B40: SEGURIDAD | C40: GORRA NEGRA SEGURIDAD | D40: =10/2 -> 5 | E40: =10/2 -> 5 | F40: =10/2 -> 5 | G40: =IF( OR(A40="",B40="",C40=""), "", CLEAN(TRIM(A40)) & "|" & CLEAN(TRIM(B40)) & "|" & CLEAN(TRIM(C40)) ) -> LIMA E ICA PROVINCIA|SEGURIDAD|GORRA NEGRA SEGURIDAD
...

Sheet Entradas
A1: Fecha | B1: LOCAL | C1: GRUPO (auto) | D1: CARGO ESTANDAR | E1: MATERIAL | F1: TALLA | G1: CANTIDAD
C2: {=IFERROR(_xlfn.XLOOKUP(B2,Locales!$A:$A,Locales!$B:$B,""),"")}
C3: {=IFERROR(_xlfn.XLOOKUP(B3,Locales!$A:$A,Locales!$B:$B,""),"")}
C4: {=IFERROR(_xlfn.XLOOKUP(B4,Locales!$A:$A,Locales!$B:$B,""),"")}
C5: {=IFERROR(_xlfn.XLOOKUP(B5,Locales!$A:$A,Locales!$B:$B,""),"")}
C6: {=IFERROR(_xlfn.XLOOKUP(B6,Locales!$A:$A,Locales!$B:$B,""),"")}
C7: {=IFERROR(_xlfn.XLOOKUP(B7,Locales!$A:$A,Locales!$B:$B,""),"")}
C8: {=IFERROR(_xlfn.XLOOKUP(B8,Locales!$A:$A,Locales!$B:$B,""),"")}
C9: {=IFERROR(_xlfn.XLOOKUP(B9,Locales!$A:$A,Locales!$B:$B,""),"")}
C10: {=IFERROR(_xlfn.XLOOKUP(B10,Locales!$A:$A,Locales!$B:$B,""),"")}
C11: {=IFERROR(_xlfn.XLOOKUP(B11,Locales!$A:$A,Locales!$B:$B,""),"")}
C12: {=IFERROR(_xlfn.XLOOKUP(B12,Locales!$A:$A,Locales!$B:$B,""),"")}
C13: {=IFERROR(_xlfn.XLOOKUP(B13,Locales!$A:$A,Locales!$B:$B,""),"")}
... C2000: {=IFERROR(_xlfn.XLOOKUP(B2000,Locales!$A:$A,Locales!$B:$B,""),"")}

Sheet Solicitudes
A1: Fecha | B1: DNI | C1: APELLIDOS Y NOMBRES (auto) | D1: LOCAL (auto) | E1: GRUPO (auto) | F1: CARGO ESTANDAR (auto) | G1: MATERIAL | H1: TALLA | I1: PRECIO (auto) | J1: CANTIDAD | K1: SUBTOTAL | L1: ESTADO | M1: Obs | N1: CLAVE
A2: 45974 | B2: 74415759 | C2: {=IFERROR(_xlfn.XLOOKUP(B2,Personal!$A:$A,Personal!$D:$D,""),"")} -> GONZALES LOZANO JAIME JUNIOR | D2: {=IFERROR(_xlfn.XLOOKUP(B2,Personal!$A:$A,Personal!$C:$C,""),"")} -> IQUITOS | E2: {=IFERROR(_xlfn.XLOOKUP(D2,Locales!$A:$A,Locales!$B:$B,""),"")} -> PATIO DE COMIDA | F2: {=IFERROR(_xlfn.XLOOKUP(B2,Personal!$A:$A,Personal!$F:$F,""),"")} -> CAJA | G2: POLO PIQUÉ CONCHE VINO, MANGA CORTA CAJA | H2: SML | I2: {=IFERROR(INDEX(Precios!$D:$F,MATCH(N2, Precios!$G:$G, 0),CHOOSE(MATCH(H2, {"SML";"XL";"XXL"}, 0), 1, 2, 3)), 0)} -> 13.5 | J2: 2 | K2: =IFERROR(I2*J2,0) -> 27 | L2: ENTREGADO | N2: =IF( OR(E2="",F2="",G2=""), "",CLEAN(TRIM(E2)) & "|" & CLEAN(TRIM(F2)) & "|" & CLEAN(TRIM(G2))) -> PATIO DE COMIDA|CAJA|POLO PIQUÉ CONCHE VINO, MANGA CORTA CAJA | O2: =IF(N2="","",IF(COUNTIF(Precios!$G:$G,N2)=0,"⚠ No coincide con Precios","OK")) -> OK
A3: 45974 | B3: 73233227 | C3: {=IFERROR(_xlfn.XLOOKUP(B3,Personal!$A:$A,Personal!$D:$D,""),"")} -> DEL CASTILLO TELLO JULIA OTILIA | D3: {=IFERROR(_xlfn.XLOOKUP(B3,Personal!$A:$A,Personal!$C:$C,""),"")} -> IQUITOS | E3: {=IFERROR(_xlfn.XLOOKUP(D3,Locales!$A:$A,Locales!$B:$B,""),"")} -> PATIO DE COMIDA | F3: {=IFERROR(_xlfn.XLOOKUP(B3,Personal!$A:$A,Personal!$F:$F,""),"")} -> COUNTER | G3: POLO PIQUÉ CONCHE VINO, MANGA CORTA COUNTER | H3: SML | I3: {=IFERROR(INDEX(Precios!$D:$F,MATCH(N3, Precios!$G:$G, 0),CHOOSE(MATCH(H3, {"SML";"XL";"XXL"}, 0), 1, 2, 3)), 0)} -> 13.5 | J3: 2 | K3: =IFERROR(I3*J3,0) -> 27 | L3: ENTREGADO | N3: =IF( OR(E3="",F3="",G3=""), "",CLEAN(TRIM(E3)) & "|" & CLEAN(TRIM(F3)) & "|" & CLEAN(TRIM(G3))) -> PATIO DE COMIDA|COUNTER|POLO PIQUÉ CONCHE VINO, MANGA CORTA COUNTER | O3: =IF(N3="","",IF(COUNTIF(Precios!$G:$G,N3)=0,"⚠ No coincide con Precios","OK")) -> OK
A4: 45974 | B4: 46192476 | C4: {=IFERROR(_xlfn.XLOOKUP(B4,Personal!$A:$A,Personal!$D:$D,""),"")} -> BABILONIA VEGA LINDA EBONY | D4: {=IFERROR(_xlfn.XLOOKUP(B4,Personal!$A:$A,Personal!$C:$C,""),"")} -> IQUITOS | E4: {=IFERROR(_xlfn.XLOOKUP(D4,Locales!$A:$A,Locales!$B:$B,""),"")} -> PATIO DE COMIDA | F4: {=IFERROR(_xlfn.XLOOKUP(B4,Personal!$A:$A,Personal!$F:$F,""),"")} -> COUNTER | G4: POLO PIQUÉ CONCHE VINO, MANGA CORTA COUNTER | H4: SML | I4: {=IFERROR(INDEX(Precios!$D:$F,MATCH(N4, Precios!$G:$G, 0),CHOOSE(MATCH(H4, {"SML";"XL";"XXL"}, 0), 1, 2, 3)), 0)} -> 13.5 | J4: 2 | K4: =IFERROR(I4*J4,0) -> 27 | L4: ENTREGADO | N4: =IF( OR(E4="",F4="",G4=""), "",CLEAN(TRIM(E4)) & "|" & CLEAN(TRIM(F4)) & "|" & CLEAN(TRIM(G4))) -> PATIO DE COMIDA|COUNTER|POLO PIQUÉ CONCHE VINO, MANGA CORTA COUNTER | O4: =IF(N4="","",IF(COUNTIF(Precios!$G:$G,N4)=0,"⚠ No coincide con Precios","OK")) -> OK
A5: 45974 | B5: 77100486 | C5: {=IFERROR(_xlfn.XLOOKUP(B5,Personal!$A:$A,Personal!$D:$D,""),"")} -> ALVAN ESCOBEDO ROSA DEL CARMEN | D5: {=IFERROR(_xlfn.XLOOKUP(B5,Personal!$A:$A,Personal!$C:$C,""),"")} -> IQUITOS | E5: {=IFERROR(_xlfn.XLOOKUP(D5,Locales!$A:$A,Locales!$B:$B,""),"")} -> PATIO DE COMIDA | F5: {=IFERROR(_xlfn.XLOOKUP(B5,Personal!$A:$A,Personal!$F:$F,""),"")} -> COUNTER | G5: POLO PIQUÉ CONCHE VINO, MANGA CORTA COUNTER | H5: SML | I5: {=IFERROR(INDEX(Precios!$D:$F,MATCH(N5, Precios!$G:$G, 0),CHOOSE(MATCH(H5, {"SML";"XL";"XXL"}, 0), 1, 2, 3)), 0)} -> 13.5 | J5: 2 | K5: =IFERROR(I5*J5,0) -> 27 | L5: ENTREGADO | N5: =IF( OR(E5="",F5="",G5=""), "",CLEAN(TRIM(E5)) & "|" & CLEAN(TRIM(F5)) & "|" & CLEAN(TRIM(G5))) -> PATIO DE COMIDA|COUNTER|POLO PIQUÉ CONCHE VINO, MANGA CORTA COUNTER | O5: =IF(N5="","",IF(COUNTIF(Precios!$G:$G,N5)=0,"⚠ No coincide con Precios","OK")) -> OK
A6: 45974 | B6: 43347817 | C6: {=IFERROR(_xlfn.XLOOKUP(B6,Personal!$A:$A,Personal!$D:$D,""),"")} -> SIAS MELENDEZ ROBIN | D6: {=IFERROR(_xlfn.XLOOKUP(B6,Personal!$A:$A,Personal!$C:$C,""),"")} -> IQUITOS | E6: {=IFERROR(_xlfn.XLOOKUP(D6,Locales!$A:$A,Locales!$B:$B,""),"")} -> PATIO DE COMIDA | F6: {=IFERROR(_xlfn.XLOOKUP(B6,Personal!$A:$A,Personal!$F:$F,""),"")} -> PRODUCCIÓN / COCINA | G6: CHAQUETA DRILL BLANCO | H6: SML | I6: {=IFERROR(INDEX(Precios!$D:$F,MATCH(N6, Precios!$G:$G, 0),CHOOSE(MATCH(H6, {"SML";"XL";"XXL"}, 0), 1, 2, 3)), 0)} -> 16.25 | J6: 2 | K6: =IFERROR(I6*J6,0) -> 32.5 | L6: ENTREGADO | N6: =IF( OR(E6="",F6="",G6=""), "",CLEAN(TRIM(E6)) & "|" & CLEAN(TRIM(F6)) & "|" & CLEAN(TRIM(G6))) -> PATIO DE COMIDA|PRODUCCIÓN / COCINA|CHAQUETA DRILL BLANCO | O6: =IF(N6="","",IF(COUNTIF(Precios!$G:$G,N6)=0,"⚠ No coincide con Precios","OK")) -> OK
A7: 45974 | B7: 43347817 | C7: {=IFERROR(_xlfn.XLOOKUP(B7,Personal!$A:$A,Personal!$D:$D,""),"")} -> SIAS MELENDEZ ROBIN | D7: {=IFERROR(_xlfn.XLOOKUP(B7,Personal!$A:$A,Personal!$C:$C,""),"")} -> IQUITOS | E7: {=IFERROR(_xlfn.XLOOKUP(D7,Locales!$A:$A,Locales!$B:$B,""),"")} -> PATIO DE COMIDA | F7: {=IFERROR(_xlfn.XLOOKUP(B7,Personal!$A:$A,Personal!$F:$F,""),"")} -> PRODUCCIÓN / COCINA | G7: PANTALÓN SAL Y PIMIENTA | H7: SML | I7: {=IFERROR(INDEX(Precios!$D:$F,MATCH(N7, Precios!$G:$G, 0),CHOOSE(MATCH(H7, {"SML";"XL";"XXL"}, 0), 1, 2, 3)), 0)} -> 11 | J7: 2 | K7: =IFERROR(I7*J7,0) -> 22 | L7: ENTREGADO | N7: =IF( OR(E7="",F7="",G7=""), "",CLEAN(TRIM(E7)) & "|" & CLEAN(TRIM(F7)) & "|" & CLEAN(TRIM(G7))) -> PATIO DE COMIDA|PRODUCCIÓN / COCINA|PANTALÓN SAL Y PIMIENTA | O7: =IF(N7="","",IF(COUNTIF(Precios!$G:$G,N7)=0,"⚠ No coincide con Precios","OK")) -> OK
A8: 45974 | B8: 43347817 | C8: {=IFERROR(_xlfn.XLOOKUP(B8,Personal!$A:$A,Personal!$D:$D,""),"")} -> SIAS MELENDEZ ROBIN | D8: {=IFERROR(_xlfn.XLOOKUP(B8,Personal!$A:$A,Personal!$C:$C,""),"")} -> IQUITOS | E8: {=IFERROR(_xlfn.XLOOKUP(D8,Locales!$A:$A,Locales!$B:$B,""),"")} -> PATIO DE COMIDA | F8: {=IFERROR(_xlfn.XLOOKUP(B8,Personal!$A:$A,Personal!$F:$F,""),"")} -> PRODUCCIÓN / COCINA | G8: PECHERA GRIS EN DRILL | H8: SML | I8: {=IFERROR(INDEX(Precios!$D:$F,MATCH(N8, Precios!$G:$G, 0),CHOOSE(MATCH(H8, {"SML";"XL";"XXL"}, 0), 1, 2, 3)), 0)} -> 6.5 | J8: 2 | K8: =IFERROR(I8*J8,0) -> 13 | L8: ENTREGADO | N8: =IF( OR(E8="",F8="",G8=""), "",CLEAN(TRIM(E8)) & "|" & CLEAN(TRIM(F8)) & "|" & CLEAN(TRIM(G8))) -> PATIO DE COMIDA|PRODUCCIÓN / COCINA|PECHERA GRIS EN DRILL | O8: =IF(N8="","",IF(COUNTIF(Precios!$G:$G,N8)=0,"⚠ No coincide con Precios","OK")) -> OK
A9: 45974 | B9: 43347817 | C9: {=IFERROR(_xlfn.XLOOKUP(B9,Personal!$A:$A,Personal!$D:$D,""),"")} -> SIAS MELENDEZ ROBIN | D9: {=IFERROR(_xlfn.XLOOKUP(B9,Personal!$A:$A,Personal!$C:$C,""),"")} -> IQUITOS | E9: {=IFERROR(_xlfn.XLOOKUP(D9,Locales!$A:$A,Locales!$B:$B,""),"")} -> PATIO DE COMIDA | F9: {=IFERROR(_xlfn.XLOOKUP(B9,Personal!$A:$A,Personal!$F:$F,""),"")} -> PRODUCCIÓN / COCINA | G9: GARIBALDI GRIS | H9: SML | I9: {=IFERROR(INDEX(Precios!$D:$F,MATCH(N9, Precios!$G:$G, 0),CHOOSE(MATCH(H9, {"SML";"XL";"XXL"}, 0), 1, 2, 3)), 0)} -> 4.5 | J9: 2 | K9: =IFERROR(I9*J9,0) -> 9 | L9: ENTREGADO | N9: =IF( OR(E9="",F9="",G9=""), "",CLEAN(TRIM(E9)) & "|" & CLEAN(TRIM(F9)) & "|" & CLEAN(TRIM(G9))) -> PATIO DE COMIDA|PRODUCCIÓN / COCINA|GARIBALDI GRIS | O9: =IF(N9="","",IF(COUNTIF(Precios!$G:$G,N9)=0,"⚠ No coincide con Precios","OK")) -> OK
A10: 45974 | B10: 43347817 | C10: {=IFERROR(_xlfn.XLOOKUP(B10,Personal!$A:$A,Personal!$D:$D,""),"")} -> SIAS MELENDEZ ROBIN | D10: {=IFERROR(_xlfn.XLOOKUP(B10,Personal!$A:$A,Personal!$C:$C,""),"")} -> IQUITOS | E10: {=IFERROR(_xlfn.XLOOKUP(D10,Locales!$A:$A,Locales!$B:$B,""),"")} -> PATIO DE COMIDA | F10: {=IFERROR(_xlfn.XLOOKUP(B10,Personal!$A:$A,Personal!$F:$F,""),"")} -> PRODUCCIÓN / COCINA | G10: POLO 30/1 GRIS | H10: SML | I10: {=IFERROR(INDEX(Precios!$D:$F,MATCH(N10, Precios!$G:$G, 0),CHOOSE(MATCH(H10, {"SML";"XL";"XXL"}, 0), 1, 2, 3)), 0)} -> 7.5 | J10: 4 | K10: =IFERROR(I10*J10,0) -> 30 | L10: ENTREGADO | N10: =IF( OR(E10="",F10="",G10=""), "",CLEAN(TRIM(E10)) & "|" & CLEAN(TRIM(F10)) & "|" & CLEAN(TRIM(G10))) -> PATIO DE COMIDA|PRODUCCIÓN / COCINA|POLO 30/1 GRIS | O10: =IF(N10="","",IF(COUNTIF(Precios!$G:$G,N10)=0,"⚠ No coincide con Precios","OK")) -> OK
A11: 45974 | B11: 62814712 | C11: {=IFERROR(_xlfn.XLOOKUP(B11,Personal!$A:$A,Personal!$D:$D,""),"")} -> PACAYA CHOTA MAYCOL | D11: {=IFERROR(_xlfn.XLOOKUP(B11,Personal!$A:$A,Personal!$C:$C,""),"")} -> IQUITOS | E11: {=IFERROR(_xlfn.XLOOKUP(D11,Locales!$A:$A,Locales!$B:$B,""),"")} -> PATIO DE COMIDA | F11: {=IFERROR(_xlfn.XLOOKUP(B11,Personal!$A:$A,Personal!$F:$F,""),"")} -> PRODUCCIÓN / COCINA | G11: CHAQUETA DRILL BLANCO | H11: SML | I11: {=IFERROR(INDEX(Precios!$D:$F,MATCH(N11, Precios!$G:$G, 0),CHOOSE(MATCH(H11, {"SML";"XL";"XXL"}, 0), 1, 2, 3)), 0)} -> 16.25 | J11: 2 | K11: =IFERROR(I11*J11,0) -> 32.5 | L11: ENTREGADO | N11: =IF( OR(E11="",F11="",G11=""), "",CLEAN(TRIM(E11)) & "|" & CLEAN(TRIM(F11)) & "|" & CLEAN(TRIM(G11))) -> PATIO DE COMIDA|PRODUCCIÓN / COCINA|CHAQUETA DRILL BLANCO | O11: =IF(N11="","",IF(COUNTIF(Precios!$G:$G,N11)=0,"⚠ No coincide con Precios","OK")) -> OK
A12: 45974 | B12: 62814712 | C12: {=IFERROR(_xlfn.XLOOKUP(B12,Personal!$A:$A,Personal!$D:$D,""),"")} -> PACAYA CHOTA MAYCOL | D12: {=IFERROR(_xlfn.XLOOKUP(B12,Personal!$A:$A,Personal!$C:$C,""),"")} -> IQUITOS | E12: {=IFERROR(_xlfn.XLOOKUP(D12,Locales!$A:$A,Locales!$B:$B,""),"")} -> PATIO DE COMIDA | F12: {=IFERROR(_xlfn.XLOOKUP(B12,Personal!$A:$A,Personal!$F:$F,""),"")} -> PRODUCCIÓN / COCINA | G12: PANTALÓN SAL Y PIMIENTA | H12: SML | I12: {=IFERROR(INDEX(Precios!$D:$F,MATCH(N12, Precios!$G:$G, 0),CHOOSE(MATCH(H12, {"SML";"XL";"XXL"}, 0), 1, 2, 3)), 0)} -> 11 | J12: 2 | K12: =IFERROR(I12*J12,0) -> 22 | L12: ENTREGADO | N12: =IF( OR(E12="",F12="",G12=""), "",CLEAN(TRIM(E12)) & "|" & CLEAN(TRIM(F12)) & "|" & CLEAN(TRIM(G12))) -> PATIO DE COMIDA|PRODUCCIÓN / COCINA|PANTALÓN SAL Y PIMIENTA | O12: =IF(N12="","",IF(COUNTIF(Precios!$G:$G,N12)=0,"⚠ No coincide con Precios","OK")) -> OK
A13: 45974 | B13: 62814712 | C13: {=IFERROR(_xlfn.XLOOKUP(B13,Personal!$A:$A,Personal!$D:$D,""),"")} -> PACAYA CHOTA MAYCOL | D13: {=IFERROR(_xlfn.XLOOKUP(B13,Personal!$A:$A,Personal!$C:$C,""),"")} -> IQUITOS | E13: {=IFERROR(_xlfn.XLOOKUP(D13,Locales!$A:$A,Locales!$B:$B,""),"")} -> PATIO DE COMIDA | F13: {=IFERROR(_xlfn.XLOOKUP(B13,Personal!$A:$A,Personal!$F:$F,""),"")} -> PRODUCCIÓN / COCINA | G13: PECHERA GRIS EN DRILL | H13: SML | I13: {=IFERROR(INDEX(Precios!$D:$F,MATCH(N13, Precios!$G:$G, 0),CHOOSE(MATCH(H13, {"SML";"XL";"XXL"}, 0), 1, 2, 3)), 0)} -> 6.5 | J13: 2 | K13: =IFERROR(I13*J13,0) -> 13 | L13: ENTREGADO | N13: =IF( OR(E13="",F13="",G13=""), "",CLEAN(TRIM(E13)) & "|" & CLEAN(TRIM(F13)) & "|" & CLEAN(TRIM(G13))) -> PATIO DE COMIDA|PRODUCCIÓN / COCINA|PECHERA GRIS EN DRILL | O13: =IF(N13="","",IF(COUNTIF(Precios!$G:$G,N13)=0,"⚠ No coincide con Precios","OK")) -> OK
... A116: 45987 | B116: 61053284 | C116: {=IFERROR(_xlfn.XLOOKUP(B116,Personal!$A:$A,Personal!$D:$D,""),"")} -> GUERRERO NAVARRO WEISSER MANUEL | D116: {=IFERROR(_xlfn.XLOOKUP(B116,Personal!$A:$A,Personal!$C:$C,""),"")} -> MIRAFLORES | E116: {=IFERROR(_xlfn.XLOOKUP(D116,Locales!$A:$A,Locales!$B:$B,""),"")} -> LIMA E ICA PROVINCIA | F116: {=IFERROR(_xlfn.XLOOKUP(B116,Personal!$A:$A,Personal!$F:$F,""),"")} -> PRODUCCIÓN / COCINA | G116: POLO 30/1 GRIS | H116: SML | I116: {=IFERROR(INDEX(Precios!$D:$F,MATCH(N116, Precios!$G:$G, 0),CHOOSE(MATCH(H116, {"SML";"XL";"XXL"}, 0), 1, 2, 3)), 0)} -> 7.5 | J116: 2 | K116: =IFERROR(I116*J116,0) -> 15 | L116: ENTREGADO | N116: =IF( OR(E116="",F116="",G116=""), "",CLEAN(TRIM(E116)) & "|" & CLEAN(TRIM(F116)) & "|" & CLEAN(TRIM(G116))) -> LIMA E ICA PROVINCIA|PRODUCCIÓN / COCINA|POLO 30/1 GRIS | O116: =IF(N116="","",IF(COUNTIF(Precios!$G:$G,N116)=0,"⚠ No coincide con Precios","OK")) -> OK
A117: 45975 | B117: 46722628 | C117: {=IFERROR(_xlfn.XLOOKUP(B117,Personal!$A:$A,Personal!$D:$D,""),"")} -> REYES RAMIREZ DIANA YOLI | D117: {=IFERROR(_xlfn.XLOOKUP(B117,Personal!$A:$A,Personal!$C:$C,""),"")} -> LARCOMAR | E117: {=IFERROR(_xlfn.XLOOKUP(D117,Locales!$A:$A,Locales!$B:$B,""),"")} -> PATIO DE COMIDA | F117: {=IFERROR(_xlfn.XLOOKUP(B117,Personal!$A:$A,Personal!$F:$F,""),"")} -> STAFF ADMINISTRATIVO | G117: POLO PIQUÉ PIZARRA RX, MANGA CORTA ADMI | H117: SML | I117: {=IFERROR(INDEX(Precios!$D:$F,MATCH(N117, Precios!$G:$G, 0),CHOOSE(MATCH(H117, {"SML";"XL";"XXL"}, 0), 1, 2, 3)), 0)} -> 15 | J117: 2 | K117: =IFERROR(I117*J117,0) -> 30 | L117: ENTREGADO | N117: =IF( OR(E117="",F117="",G117=""), "",CLEAN(TRIM(E117)) & "|" & CLEAN(TRIM(F117)) & "|" & CLEAN(TRIM(G117))) -> PATIO DE COMIDA|STAFF ADMINISTRATIVO|POLO PIQUÉ PIZARRA RX, MANGA CORTA ADMI | O117: =IF(N117="","",IF(COUNTIF(Precios!$G:$G,N117)=0,"⚠ No coincide con Precios","OK")) -> OK
A118: 45975 | B118: 46722628 | C118: {=IFERROR(_xlfn.XLOOKUP(B118,Personal!$A:$A,Personal!$D:$D,""),"")} -> REYES RAMIREZ DIANA YOLI | D118: {=IFERROR(_xlfn.XLOOKUP(B118,Personal!$A:$A,Personal!$C:$C,""),"")} -> LARCOMAR | E118: {=IFERROR(_xlfn.XLOOKUP(D118,Locales!$A:$A,Locales!$B:$B,""),"")} -> PATIO DE COMIDA | F118: {=IFERROR(_xlfn.XLOOKUP(B118,Personal!$A:$A,Personal!$F:$F,""),"")} -> STAFF ADMINISTRATIVO | G118: GORRO NEGRO ADM | H118: SML | I118: {=IFERROR(INDEX(Precios!$D:$F,MATCH(N118, Precios!$G:$G, 0),CHOOSE(MATCH(H118, {"SML";"XL";"XXL"}, 0), 1, 2, 3)), 0)} -> 5 | J118: 2 | K118: =IFERROR(I118*J118,0) -> 10 | L118: ENTREGADO | N118: =IF( OR(E118="",F118="",G118=""), "",CLEAN(TRIM(E118)) & "|" & CLEAN(TRIM(F118)) & "|" & CLEAN(TRIM(G118))) -> PATIO DE COMIDA|STAFF ADMINISTRATIVO|GORRO NEGRO ADM | O118: =IF(N118="","",IF(COUNTIF(Precios!$G:$G,N118)=0,"⚠ No coincide con Precios","OK")) -> OK
A119: 45975 | B119: 72670432 | C119: {=IFERROR(_xlfn.XLOOKUP(B119,Personal!$A:$A,Personal!$D:$D,""),"")} -> PAREDES MAGUIÑA HUGO RAFAEL | D119: {=IFERROR(_xlfn.XLOOKUP(B119,Personal!$A:$A,Personal!$C:$C,""),"")} -> LARCOMAR | E119: {=IFERROR(_xlfn.XLOOKUP(D119,Locales!$A:$A,Locales!$B:$B,""),"")} -> PATIO DE COMIDA | F119: {=IFERROR(_xlfn.XLOOKUP(B119,Personal!$A:$A,Personal!$F:$F,""),"")} -> STAFF ADMINISTRATIVO | G119: GORRO NEGRO ADM | H119: SML | I119: {=IFERROR(INDEX(Precios!$D:$F,MATCH(N119, Precios!$G:$G, 0),CHOOSE(MATCH(H119, {"SML";"XL";"XXL"}, 0), 1, 2, 3)), 0)} -> 5 | J119: 2 | K119: =IFERROR(I119*J119,0) -> 10 | L119: ENTREGADO | N119: =IF( OR(E119="",F119="",G119=""), "",CLEAN(TRIM(E119)) & "|" & CLEAN(TRIM(F119)) & "|" & CLEAN(TRIM(G119))) -> PATIO DE COMIDA|STAFF ADMINISTRATIVO|GORRO NEGRO ADM | O119: =IF(N119="","",IF(COUNTIF(Precios!$G:$G,N119)=0,"⚠ No coincide con Precios","OK")) -> OK
A120: 45902 | B120: 41983477 | C120: {=IFERROR(_xlfn.XLOOKUP(B120,Personal!$A:$A,Personal!$D:$D,""),"")} -> ZAPATA HERRERA FRANKLYN RICARDO | D120: {=IFERROR(_xlfn.XLOOKUP(B120,Personal!$A:$A,Personal!$C:$C,""),"")} -> JESUS MARIA | E120: {=IFERROR(_xlfn.XLOOKUP(D120,Locales!$A:$A,Locales!$B:$B,""),"")} -> LIMA E ICA PROVINCIA | F120: {=IFERROR(_xlfn.XLOOKUP(B120,Personal!$A:$A,Personal!$F:$F,""),"")} -> MOZO | G120: CAMISA BLANCA (MANGA LARGA) | H120: SML | I120: {=IFERROR(INDEX(Precios!$D:$F,MATCH(N120, Precios!$G:$G, 0),CHOOSE(MATCH(H120, {"SML";"XL";"XXL"}, 0), 1, 2, 3)), 0)} -> 18.5 | J120: 2 | K120: =IFERROR(I120*J120,0) -> 37 | L120: ENTREGADO | N120: =IF( OR(E120="",F120="",G120=""), "",CLEAN(TRIM(E120)) & "|" & CLEAN(TRIM(F120)) & "|" & CLEAN(TRIM(G120))) -> LIMA E ICA PROVINCIA|MOZO|CAMISA BLANCA (MANGA LARGA) | O120: =IF(N120="","",IF(COUNTIF(Precios!$G:$G,N120)=0,"⚠ No coincide con Precios","OK")) -> OK
A121: 45902 | B121: 41983477 | C121: {=IFERROR(_xlfn.XLOOKUP(B121,Personal!$A:$A,Personal!$D:$D,""),"")} -> ZAPATA HERRERA FRANKLYN RICARDO | D121: {=IFERROR(_xlfn.XLOOKUP(B121,Personal!$A:$A,Personal!$C:$C,""),"")} -> JESUS MARIA | E121: {=IFERROR(_xlfn.XLOOKUP(D121,Locales!$A:$A,Locales!$B:$B,""),"")} -> LIMA E ICA PROVINCIA | F121: {=IFERROR(_xlfn.XLOOKUP(B121,Personal!$A:$A,Personal!$F:$F,""),"")} -> MOZO | G121: MANDILON DRILL NEGRO | H121: SML | I121: {=IFERROR(INDEX(Precios!$D:$F,MATCH(N121, Precios!$G:$G, 0),CHOOSE(MATCH(H121, {"SML";"XL";"XXL"}, 0), 1, 2, 3)), 0)} -> 7 | J121: 2 | K121: =IFERROR(I121*J121,0) -> 14 | L121: ENTREGADO | N121: =IF( OR(E121="",F121="",G121=""), "",CLEAN(TRIM(E121)) & "|" & CLEAN(TRIM(F121)) & "|" & CLEAN(TRIM(G121))) -> LIMA E ICA PROVINCIA|MOZO|MANDILON DRILL NEGRO | O121: =IF(N121="","",IF(COUNTIF(Precios!$G:$G,N121)=0,"⚠ No coincide con Precios","OK")) -> OK
A122: 45902 | B122: 41983477 | C122: {=IFERROR(_xlfn.XLOOKUP(B122,Personal!$A:$A,Personal!$D:$D,""),"")} -> ZAPATA HERRERA FRANKLYN RICARDO | D122: {=IFERROR(_xlfn.XLOOKUP(B122,Personal!$A:$A,Personal!$C:$C,""),"")} -> JESUS MARIA | E122: {=IFERROR(_xlfn.XLOOKUP(D122,Locales!$A:$A,Locales!$B:$B,""),"")} -> LIMA E ICA PROVINCIA | F122: {=IFERROR(_xlfn.XLOOKUP(B122,Personal!$A:$A,Personal!$F:$F,""),"")} -> MOZO | G122: ANDARIN GRANATE | H122: SML | I122: {=IFERROR(INDEX(Precios!$D:$F,MATCH(N122, Precios!$G:$G, 0),CHOOSE(MATCH(H122, {"SML";"XL";"XXL"}, 0), 1, 2, 3)), 0)} -> 1.75 | J122: 2 | K122: =IFERROR(I122*J122,0) -> 3.5 | L122: ENTREGADO | N122: =IF( OR(E122="",F122="",G122=""), "",CLEAN(TRIM(E122)) & "|" & CLEAN(TRIM(F122)) & "|" & CLEAN(TRIM(G122))) -> LIMA E ICA PROVINCIA|MOZO|ANDARIN GRANATE | O122: =IF(N122="","",IF(COUNTIF(Precios!$G:$G,N122)=0,"⚠ No coincide con Precios","OK")) -> OK
A123: 45973 | B123: 47115854 | C123: {=IFERROR(_xlfn.XLOOKUP(B123,Personal!$A:$A,Personal!$D:$D,""),"")} -> JULCA DIAZ EDGAR | D123: {=IFERROR(_xlfn.XLOOKUP(B123,Personal!$A:$A,Personal!$C:$C,""),"")} -> JESUS MARIA | E123: {=IFERROR(_xlfn.XLOOKUP(D123,Locales!$A:$A,Locales!$B:$B,""),"")} -> LIMA E ICA PROVINCIA | F123: {=IFERROR(_xlfn.XLOOKUP(B123,Personal!$A:$A,Personal!$F:$F,""),"")} -> PRODUCCIÓN / COCINA | G123: CHAQUETA DRILL BLANCO | H123: SML | I123: {=IFERROR(INDEX(Precios!$D:$F,MATCH(N123, Precios!$G:$G, 0),CHOOSE(MATCH(H123, {"SML";"XL";"XXL"}, 0), 1, 2, 3)), 0)} -> 16.25 | J123: 2 | K123: =IFERROR(I123*J123,0) -> 32.5 | L123: ENTREGADO | N123: =IF( OR(E123="",F123="",G123=""), "",CLEAN(TRIM(E123)) & "|" & CLEAN(TRIM(F123)) & "|" & CLEAN(TRIM(G123))) -> LIMA E ICA PROVINCIA|PRODUCCIÓN / COCINA|CHAQUETA DRILL BLANCO | O123: =IF(N123="","",IF(COUNTIF(Precios!$G:$G,N123)=0,"⚠ No coincide con Precios","OK")) -> OK
A124: 45973 | B124: 47115854 | C124: {=IFERROR(_xlfn.XLOOKUP(B124,Personal!$A:$A,Personal!$D:$D,""),"")} -> JULCA DIAZ EDGAR | D124: {=IFERROR(_xlfn.XLOOKUP(B124,Personal!$A:$A,Personal!$C:$C,""),"")} -> JESUS MARIA | E124: {=IFERROR(_xlfn.XLOOKUP(D124,Locales!$A:$A,Locales!$B:$B,""),"")} -> LIMA E ICA PROVINCIA | F124: {=IFERROR(_xlfn.XLOOKUP(B124,Personal!$A:$A,Personal!$F:$F,""),"")} -> PRODUCCIÓN / COCINA | G124: PANTALÓN SAL Y PIMIENTA | H124: SML | I124: {=IFERROR(INDEX(Precios!$D:$F,MATCH(N124, Precios!$G:$G, 0),CHOOSE(MATCH(H124, {"SML";"XL";"XXL"}, 0), 1, 2, 3)), 0)} -> 11 | J124: 2 | K124: =IFERROR(I124*J124,0) -> 22 | L124: ENTREGADO | N124: =IF( OR(E124="",F124="",G124=""), "",CLEAN(TRIM(E124)) & "|" & CLEAN(TRIM(F124)) & "|" & CLEAN(TRIM(G124))) -> LIMA E ICA PROVINCIA|PRODUCCIÓN / COCINA|PANTALÓN SAL Y PIMIENTA | O124: =IF(N124="","",IF(COUNTIF(Precios!$G:$G,N124)=0,"⚠ No coincide con Precios","OK")) -> OK
A125: 45973 | B125: 47115854 | C125: {=IFERROR(_xlfn.XLOOKUP(B125,Personal!$A:$A,Personal!$D:$D,""),"")} -> JULCA DIAZ EDGAR | D125: {=IFERROR(_xlfn.XLOOKUP(B125,Personal!$A:$A,Personal!$C:$C,""),"")} -> JESUS MARIA | E125: {=IFERROR(_xlfn.XLOOKUP(D125,Locales!$A:$A,Locales!$B:$B,""),"")} -> LIMA E ICA PROVINCIA | F125: {=IFERROR(_xlfn.XLOOKUP(B125,Personal!$A:$A,Personal!$F:$F,""),"")} -> PRODUCCIÓN / COCINA | G125: PECHERA GRIS EN DRILL | H125: SML | I125: {=IFERROR(INDEX(Precios!$D:$F,MATCH(N125, Precios!$G:$G, 0),CHOOSE(MATCH(H125, {"SML";"XL";"XXL"}, 0), 1, 2, 3)), 0)} -> 6.5 | J125: 2 | K125: =IFERROR(I125*J125,0) -> 13 | L125: ENTREGADO | N125: =IF( OR(E125="",F125="",G125=""), "",CLEAN(TRIM(E125)) & "|" & CLEAN(TRIM(F125)) & "|" & CLEAN(TRIM(G125))) -> LIMA E ICA PROVINCIA|PRODUCCIÓN / COCINA|PECHERA GRIS EN DRILL | O125: =IF(N125="","",IF(COUNTIF(Precios!$G:$G,N125)=0,"⚠ No coincide con Precios","OK")) -> OK
A126: 45973 | B126: 47115854 | C126: {=IFERROR(_xlfn.XLOOKUP(B126,Personal!$A:$A,Personal!$D:$D,""),"")} -> JULCA DIAZ EDGAR | D126: {=IFERROR(_xlfn.XLOOKUP(B126,Personal!$A:$A,Personal!$C:$C,""),"")} -> JESUS MARIA | E126: {=IFERROR(_xlfn.XLOOKUP(D126,Locales!$A:$A,Locales!$B:$B,""),"")} -> LIMA E ICA PROVINCIA | F126: {=IFERROR(_xlfn.XLOOKUP(B126,Personal!$A:$A,Personal!$F:$F,""),"")} -> PRODUCCIÓN / COCINA | G126: GARIBALDI GRIS | H126: SML | I126: {=IFERROR(INDEX(Precios!$D:$F,MATCH(N126, Precios!$G:$G, 0),CHOOSE(MATCH(H126, {"SML";"XL";"XXL"}, 0), 1, 2, 3)), 0)} -> 4.5 | J126: 2 | K126: =IFERROR(I126*J126,0) -> 9 | L126: ENTREGADO | N126: =IF( OR(E126="",F126="",G126=""), "",CLEAN(TRIM(E126)) & "|" & CLEAN(TRIM(F126)) & "|" & CLEAN(TRIM(G126))) -> LIMA E ICA PROVINCIA|PRODUCCIÓN / COCINA|GARIBALDI GRIS | O126: =IF(N126="","",IF(COUNTIF(Precios!$G:$G,N126)=0,"⚠ No coincide con Precios","OK")) -> OK
A127: 45973 | B127: 47115854 | C127: {=IFERROR(_xlfn.XLOOKUP(B127,Personal!$A:$A,Personal!$D:$D,""),"")} -> JULCA DIAZ EDGAR | D127: {=IFERROR(_xlfn.XLOOKUP(B127,Personal!$A:$A,Personal!$C:$C,""),"")} -> JESUS MARIA | E127: {=IFERROR(_xlfn.XLOOKUP(D127,Locales!$A:$A,Locales!$B:$B,""),"")} -> LIMA E ICA PROVINCIA | F127: {=IFERROR(_xlfn.XLOOKUP(B127,Personal!$A:$A,Personal!$F:$F,""),"")} -> PRODUCCIÓN / COCINA | G127: POLO 30/1 GRIS | H127: SML | I127: {=IFERROR(INDEX(Precios!$D:$F,MATCH(N127, Precios!$G:$G, 0),CHOOSE(MATCH(H127, {"SML";"XL";"XXL"}, 0), 1, 2, 3)), 0)} -> 7.5 | J127: 2 | K127: =IFERROR(I127*J127,0) -> 15 | L127: ENTREGADO | N127: =IF( OR(E127="",F127="",G127=""), "",CLEAN(TRIM(E127)) & "|" & CLEAN(TRIM(F127)) & "|" & CLEAN(TRIM(G127))) -> LIMA E ICA PROVINCIA|PRODUCCIÓN / COCINA|POLO 30/1 GRIS | O127: =IF(N127="","",IF(COUNTIF(Precios!$G:$G,N127)=0,"⚠ No coincide con Precios","OK")) -> OK
A128: 45943 | B128: 32933368 | C128: {=IFERROR(_xlfn.XLOOKUP(B128,Personal!$A:$A,Personal!$D:$D,""),"")} -> MUÑOZ TORRES MARTHA YNES | D128: {=IFERROR(_xlfn.XLOOKUP(B128,Personal!$A:$A,Personal!$C:$C,""),"")} -> JESUS MARIA | E128: {=IFERROR(_xlfn.XLOOKUP(D128,Locales!$A:$A,Locales!$B:$B,""),"")} -> LIMA E ICA PROVINCIA | F128: {=IFERROR(_xlfn.XLOOKUP(B128,Personal!$A:$A,Personal!$F:$F,""),"")} -> PRODUCCIÓN / COCINA | G128: CHAQUETA DRILL BLANCO | H128: SML | I128: {=IFERROR(INDEX(Precios!$D:$F,MATCH(N128, Precios!$G:$G, 0),CHOOSE(MATCH(H128, {"SML";"XL";"XXL"}, 0), 1, 2, 3)), 0)} -> 16.25 | J128: 2 | K128: =IFERROR(I128*J128,0) -> 32.5 | L128: ENTREGADO | N128: =IF( OR(E128="",F128="",G128=""), "",CLEAN(TRIM(E128)) & "|" & CLEAN(TRIM(F128)) & "|" & CLEAN(TRIM(G128))) -> LIMA E ICA PROVINCIA|PRODUCCIÓN / COCINA|CHAQUETA DRILL BLANCO | O128: =IF(N128="","",IF(COUNTIF(Precios!$G:$G,N128)=0,"⚠ No coincide con Precios","OK")) -> OK
A129: 45943 | B129: 32933368 | C129: {=IFERROR(_xlfn.XLOOKUP(B129,Personal!$A:$A,Personal!$D:$D,""),"")} -> MUÑOZ TORRES MARTHA YNES | D129: {=IFERROR(_xlfn.XLOOKUP(B129,Personal!$A:$A,Personal!$C:$C,""),"")} -> JESUS MARIA | E129: {=IFERROR(_xlfn.XLOOKUP(D129,Locales!$A:$A,Locales!$B:$B,""),"")} -> LIMA E ICA PROVINCIA | F129: {=IFERROR(_xlfn.XLOOKUP(B129,Personal!$A:$A,Personal!$F:$F,""),"")} -> PRODUCCIÓN / COCINA | G129: PANTALÓN SAL Y PIMIENTA | H129: SML | I129: {=IFERROR(INDEX(Precios!$D:$F,MATCH(N129, Precios!$G:$G, 0),CHOOSE(MATCH(H129, {"SML";"XL";"XXL"}, 0), 1, 2, 3)), 0)} -> 11 | J129: 2 | K129: =IFERROR(I129*J129,0) -> 22 | L129: ENTREGADO | N129: =IF( OR(E129="",F129="",G129=""), "",CLEAN(TRIM(E129)) & "|" & CLEAN(TRIM(F129)) & "|" & CLEAN(TRIM(G129))) -> LIMA E ICA PROVINCIA|PRODUCCIÓN / COCINA|PANTALÓN SAL Y PIMIENTA | O129: =IF(N129="","",IF(COUNTIF(Precios!$G:$G,N129)=0,"⚠ No coincide con Precios","OK")) -> OK
A130: 45943 | B130: 32933368 | C130: {=IFERROR(_xlfn.XLOOKUP(B130,Personal!$A:$A,Personal!$D:$D,""),"")} -> MUÑOZ TORRES MARTHA YNES | D130: {=IFERROR(_xlfn.XLOOKUP(B130,Personal!$A:$A,Personal!$C:$C,""),"")} -> JESUS MARIA | E130: {=IFERROR(_xlfn.XLOOKUP(D130,Locales!$A:$A,Locales!$B:$B,""),"")} -> LIMA E ICA PROVINCIA | F130: {=IFERROR(_xlfn.XLOOKUP(B130,Personal!$A:$A,Personal!$F:$F,""),"")} -> PRODUCCIÓN / COCINA | G130: PECHERA GRIS EN DRILL | H130: SML | I130: {=IFERROR(INDEX(Precios!$D:$F,MATCH(N130, Precios!$G:$G, 0),CHOOSE(MATCH(H130, {"SML";"XL";"XXL"}, 0), 1, 2, 3)), 0)} -> 6.5 | J130: 2 | K130: =IFERROR(I130*J130,0) -> 13 | L130: ENTREGADO | N130: =IF( OR(E130="",F130="",G130=""), "",CLEAN(TRIM(E130)) & "|" & CLEAN(TRIM(F130)) & "|" & CLEAN(TRIM(G130))) -> LIMA E ICA PROVINCIA|PRODUCCIÓN / COCINA|PECHERA GRIS EN DRILL | O130: =IF(N130="","",IF(COUNTIF(Precios!$G:$G,N130)=0,"⚠ No coincide con Precios","OK")) -> OK
... A215: 46010 | B215: 46831171 | C215: {=IFERROR(_xlfn.XLOOKUP(B215,Personal!$A:$A,Personal!$D:$D,""),"")} -> SANCHEZ LLOCLLA ROGER YAISON | D215: {=IFERROR(_xlfn.XLOOKUP(B215,Personal!$A:$A,Personal!$C:$C,""),"")} -> VCH-ADM | E215: {=IFERROR(_xlfn.XLOOKUP(D215,Locales!$A:$A,Locales!$B:$B,""),"")} -> LIMA E ICA PROVINCIA | F215: {=IFERROR(_xlfn.XLOOKUP(B215,Personal!$A:$A,Personal!$F:$F,""),"")} -> BAR | G215: POLO 30/1 GRIS | H215: SML | I215: {=IFERROR(INDEX(Precios!$D:$F,MATCH(N215, Precios!$G:$G, 0),CHOOSE(MATCH(H215, {"SML";"XL";"XXL"}, 0), 1, 2, 3)), 0)} -> 7.5 | J215: 2 | K215: =IFERROR(I215*J215,0) -> 15 | L215: ENTREGADO | N215: =IF( OR(E215="",F215="",G215=""), "",CLEAN(TRIM(E215)) & "|" & CLEAN(TRIM(F215)) & "|" & CLEAN(TRIM(G215))) -> LIMA E ICA PROVINCIA|BAR|POLO 30/1 GRIS | O215: =IF(N215="","",IF(COUNTIF(Precios!$G:$G,N215)=0,"⚠ No coincide con Precios","OK")) -> OK
C216: {=IFERROR(_xlfn.XLOOKUP(B216,Personal!$A:$A,Personal!$D:$D,""),"")} -> 0 | D216: {=IFERROR(_xlfn.XLOOKUP(B216,Personal!$A:$A,Personal!$C:$C,""),"")} -> 0 | E216: {=IFERROR(_xlfn.XLOOKUP(D216,Locales!$A:$A,Locales!$B:$B,""),"")} | F216: {=IFERROR(_xlfn.XLOOKUP(B216,Personal!$A:$A,Personal!$F:$F,""),"")} -> 0 | I216: {=IFERROR(INDEX(Precios!$D:$F,MATCH(N216, Precios!$G:$G, 0),CHOOSE(MATCH(H216, {"SML";"XL";"XXL"}, 0), 1, 2, 3)), 0)} -> 0 | K216: =IFERROR(I216*J216,0) -> 0 | N216: =IF( OR(E216="",F216="",G216=""), "",CLEAN(TRIM(E216)) & "|" & CLEAN(TRIM(F216)) & "|" & CLEAN(TRIM(G216))) | O216: =IF(N216="","",IF(COUNTIF(Precios!$G:$G,N216)=0,"⚠ No coincide con Precios","OK"))
C217: {=IFERROR(_xlfn.XLOOKUP(B217,Personal!$A:$A,Personal!$D:$D,""),"")} -> 0 | D217: {=IFERROR(_xlfn.XLOOKUP(B217,Personal!$A:$A,Personal!$C:$C,""),"")} -> 0 | E217: {=IFERROR(_xlfn.XLOOKUP(D217,Locales!$A:$A,Locales!$B:$B,""),"")} | F217: {=IFERROR(_xlfn.XLOOKUP(B217,Personal!$A:$A,Personal!$F:$F,""),"")} -> 0 | I217: {=IFERROR(INDEX(Precios!$D:$F,MATCH(N217, Precios!$G:$G, 0),CHOOSE(MATCH(H217, {"SML";"XL";"XXL"}, 0), 1, 2, 3)), 0)} -> 0 | K217: =IFERROR(I217*J217,0) -> 0 | N217: =IF( OR(E217="",F217="",G217=""), "",CLEAN(TRIM(E217)) & "|" & CLEAN(TRIM(F217)) & "|" & CLEAN(TRIM(G217))) | O217: =IF(N217="","",IF(COUNTIF(Precios!$G:$G,N217)=0,"⚠ No coincide con Precios","OK"))
C218: {=IFERROR(_xlfn.XLOOKUP(B218,Personal!$A:$A,Personal!$D:$D,""),"")} -> 0 | D218: {=IFERROR(_xlfn.XLOOKUP(B218,Personal!$A:$A,Personal!$C:$C,""),"")} -> 0 | E218: {=IFERROR(_xlfn.XLOOKUP(D218,Locales!$A:$A,Locales!$B:$B,""),"")} | F218: {=IFERROR(_xlfn.XLOOKUP(B218,Personal!$A:$A,Personal!$F:$F,""),"")} -> 0 | I218: {=IFERROR(INDEX(Precios!$D:$F,MATCH(N218, Precios!$G:$G, 0),CHOOSE(MATCH(H218, {"SML";"XL";"XXL"}, 0), 1, 2, 3)), 0)} -> 0 | K218: =IFERROR(I218*J218,0) -> 0 | N218: =IF( OR(E218="",F218="",G218=""), "",CLEAN(TRIM(E218)) & "|" & CLEAN(TRIM(F218)) & "|" & CLEAN(TRIM(G218))) | O218: =IF(N218="","",IF(COUNTIF(Precios!$G:$G,N218)=0,"⚠ No coincide con Precios","OK"))
C219: {=IFERROR(_xlfn.XLOOKUP(B219,Personal!$A:$A,Personal!$D:$D,""),"")} -> 0 | D219: {=IFERROR(_xlfn.XLOOKUP(B219,Personal!$A:$A,Personal!$C:$C,""),"")} -> 0 | E219: {=IFERROR(_xlfn.XLOOKUP(D219,Locales!$A:$A,Locales!$B:$B,""),"")} | F219: {=IFERROR(_xlfn.XLOOKUP(B219,Personal!$A:$A,Personal!$F:$F,""),"")} -> 0 | I219: {=IFERROR(INDEX(Precios!$D:$F,MATCH(N219, Precios!$G:$G, 0),CHOOSE(MATCH(H219, {"SML";"XL";"XXL"}, 0), 1, 2, 3)), 0)} -> 0 | K219: =IFERROR(I219*J219,0) -> 0 | N219: =IF( OR(E219="",F219="",G219=""), "",CLEAN(TRIM(E219)) & "|" & CLEAN(TRIM(F219)) & "|" & CLEAN(TRIM(G219))) | O219: =IF(N219="","",IF(COUNTIF(Precios!$G:$G,N219)=0,"⚠ No coincide con Precios","OK"))
C220: {=IFERROR(_xlfn.XLOOKUP(B220,Personal!$A:$A,Personal!$D:$D,""),"")} -> 0 | D220: {=IFERROR(_xlfn.XLOOKUP(B220,Personal!$A:$A,Personal!$C:$C,""),"")} -> 0 | E220: {=IFERROR(_xlfn.XLOOKUP(D220,Locales!$A:$A,Locales!$B:$B,""),"")} | F220: {=IFERROR(_xlfn.XLOOKUP(B220,Personal!$A:$A,Personal!$F:$F,""),"")} -> 0 | I220: {=IFERROR(INDEX(Precios!$D:$F,MATCH(N220, Precios!$G:$G, 0),CHOOSE(MATCH(H220, {"SML";"XL";"XXL"}, 0), 1, 2, 3)), 0)} -> 0 | K220: =IFERROR(I220*J220,0) -> 0 | N220: =IF( OR(E220="",F220="",G220=""), "",CLEAN(TRIM(E220)) & "|" & CLEAN(TRIM(F220)) & "|" & CLEAN(TRIM(G220))) | O220: =IF(N220="","",IF(COUNTIF(Precios!$G:$G,N220)=0,"⚠ No coincide con Precios","OK"))
C221: {=IFERROR(_xlfn.XLOOKUP(B221,Personal!$A:$A,Personal!$D:$D,""),"")} -> 0 | D221: {=IFERROR(_xlfn.XLOOKUP(B221,Personal!$A:$A,Personal!$C:$C,""),"")} -> 0 | E221: {=IFERROR(_xlfn.XLOOKUP(D221,Locales!$A:$A,Locales!$B:$B,""),"")} | F221: {=IFERROR(_xlfn.XLOOKUP(B221,Personal!$A:$A,Personal!$F:$F,""),"")} -> 0 | I221: {=IFERROR(INDEX(Precios!$D:$F,MATCH(N221, Precios!$G:$G, 0),CHOOSE(MATCH(H221, {"SML";"XL";"XXL"}, 0), 1, 2, 3)), 0)} -> 0 | K221: =IFERROR(I221*J221,0) -> 0 | N221: =IF( OR(E221="",F221="",G221=""), "",CLEAN(TRIM(E221)) & "|" & CLEAN(TRIM(F221)) & "|" & CLEAN(TRIM(G221))) | O221: =IF(N221="","",IF(COUNTIF(Precios!$G:$G,N221)=0,"⚠ No coincide con Precios","OK"))
C222: {=IFERROR(_xlfn.XLOOKUP(B222,Personal!$A:$A,Personal!$D:$D,""),"")} -> 0 | D222: {=IFERROR(_xlfn.XLOOKUP(B222,Personal!$A:$A,Personal!$C:$C,""),"")} -> 0 | E222: {=IFERROR(_xlfn.XLOOKUP(D222,Locales!$A:$A,Locales!$B:$B,""),"")} | F222: {=IFERROR(_xlfn.XLOOKUP(B222,Personal!$A:$A,Personal!$F:$F,""),"")} -> 0 | I222: {=IFERROR(INDEX(Precios!$D:$F,MATCH(N222, Precios!$G:$G, 0),CHOOSE(MATCH(H222, {"SML";"XL";"XXL"}, 0), 1, 2, 3)), 0)} -> 0 | K222: =IFERROR(I222*J222,0) -> 0 | N222: =IF( OR(E222="",F222="",G222=""), "",CLEAN(TRIM(E222)) & "|" & CLEAN(TRIM(F222)) & "|" & CLEAN(TRIM(G222))) | O222: =IF(N222="","",IF(COUNTIF(Precios!$G:$G,N222)=0,"⚠ No coincide con Precios","OK"))
C223: {=IFERROR(_xlfn.XLOOKUP(B223,Personal!$A:$A,Personal!$D:$D,""),"")} -> 0 | D223: {=IFERROR(_xlfn.XLOOKUP(B223,Personal!$A:$A,Personal!$C:$C,""),"")} -> 0 | E223: {=IFERROR(_xlfn.XLOOKUP(D223,Locales!$A:$A,Locales!$B:$B,""),"")} | F223: {=IFERROR(_xlfn.XLOOKUP(B223,Personal!$A:$A,Personal!$F:$F,""),"")} -> 0 | I223: {=IFERROR(INDEX(Precios!$D:$F,MATCH(N223, Precios!$G:$G, 0),CHOOSE(MATCH(H223, {"SML";"XL";"XXL"}, 0), 1, 2, 3)), 0)} -> 0 | K223: =IFERROR(I223*J223,0) -> 0 | N223: =IF( OR(E223="",F223="",G223=""), "",CLEAN(TRIM(E223)) & "|" & CLEAN(TRIM(F223)) & "|" & CLEAN(TRIM(G223))) | O223: =IF(N223="","",IF(COUNTIF(Precios!$G:$G,N223)=0,"⚠ No coincide con Precios","OK"))
C224: {=IFERROR(_xlfn.XLOOKUP(B224,Personal!$A:$A,Personal!$D:$D,""),"")} -> 0 | D224: {=IFERROR(_xlfn.XLOOKUP(B224,Personal!$A:$A,Personal!$C:$C,""),"")} -> 0 | E224: {=IFERROR(_xlfn.XLOOKUP(D224,Locales!$A:$A,Locales!$B:$B,""),"")} | F224: {=IFERROR(_xlfn.XLOOKUP(B224,Personal!$A:$A,Personal!$F:$F,""),"")} -> 0 | I224: {=IFERROR(INDEX(Precios!$D:$F,MATCH(N224, Precios!$G:$G, 0),CHOOSE(MATCH(H224, {"SML";"XL";"XXL"}, 0), 1, 2, 3)), 0)} -> 0 | K224: =IFERROR(I224*J224,0) -> 0 | N224: =IF( OR(E224="",F224="",G224=""), "",CLEAN(TRIM(E224)) & "|" & CLEAN(TRIM(F224)) & "|" & CLEAN(TRIM(G224))) | O224: =IF(N224="","",IF(COUNTIF(Precios!$G:$G,N224)=0,"⚠ No coincide con Precios","OK"))
C225: {=IFERROR(_xlfn.XLOOKUP(B225,Personal!$A:$A,Personal!$D:$D,""),"")} -> 0 | D225: {=IFERROR(_xlfn.XLOOKUP(B225,Personal!$A:$A,Personal!$C:$C,""),"")} -> 0 | E225: {=IFERROR(_xlfn.XLOOKUP(D225,Locales!$A:$A,Locales!$B:$B,""),"")} | F225: {=IFERROR(_xlfn.XLOOKUP(B225,Personal!$A:$A,Personal!$F:$F,""),"")} -> 0 | I225: {=IFERROR(INDEX(Precios!$D:$F,MATCH(N225, Precios!$G:$G, 0),CHOOSE(MATCH(H225, {"SML";"XL";"XXL"}, 0), 1, 2, 3)), 0)} -> 0 | K225: =IFERROR(I225*J225,0) -> 0 | N225: =IF( OR(E225="",F225="",G225=""), "",CLEAN(TRIM(E225)) & "|" & CLEAN(TRIM(F225)) & "|" & CLEAN(TRIM(G225))) | O225: =IF(N225="","",IF(COUNTIF(Precios!$G:$G,N225)=0,"⚠ No coincide con Precios","OK"))
C226: {=IFERROR(_xlfn.XLOOKUP(B226,Personal!$A:$A,Personal!$D:$D,""),"")} -> 0 | D226: {=IFERROR(_xlfn.XLOOKUP(B226,Personal!$A:$A,Personal!$C:$C,""),"")} -> 0 | E226: {=IFERROR(_xlfn.XLOOKUP(D226,Locales!$A:$A,Locales!$B:$B,""),"")} | F226: {=IFERROR(_xlfn.XLOOKUP(B226,Personal!$A:$A,Personal!$F:$F,""),"")} -> 0 | I226: {=IFERROR(INDEX(Precios!$D:$F,MATCH(N226, Precios!$G:$G, 0),CHOOSE(MATCH(H226, {"SML";"XL";"XXL"}, 0), 1, 2, 3)), 0)} -> 0 | K226: =IFERROR(I226*J226,0) -> 0 | N226: =IF( OR(E226="",F226="",G226=""), "",CLEAN(TRIM(E226)) & "|" & CLEAN(TRIM(F226)) & "|" & CLEAN(TRIM(G226))) | O226: =IF(N226="","",IF(COUNTIF(Precios!$G:$G,N226)=0,"⚠ No coincide con Precios","OK"))
...

Sheet Descuentos
A1: DNI | B1: RAZON SOCIAL | C1: LOCAL | D1: APELLIDOS Y NOMBRES | E1: CARGO ESTANDAR | F1: FECHA INGRESO | G1: FECHA DE ENTREGA | H1: MONEDA | I1: DESCUENTO
A2: 74415759 | B2: TREND BUSINES S.A.C. | C2: IQUITOS | D2: GONZALES LOZANO JAIME JUNIOR | E2: CAJA | F2: 45733 | G2: 45974 | H2: S/ | I2: 27
A3: 73233227 | B3: TREND BUSINESS S.A.C. | C3: IQUITOS | D3: DEL CASTILLO TELLO JULIA OTILIA | E3: COUNTER | F3: 45870 | G3: 45974 | H3: S/ | I3: 27
A4: 46192476 | B4: TREND BUSINESS S.A.C. | C4: IQUITOS | D4: BABILONIA VEGA LINDA EBONY | E4: COUNTER | F4: 45901 | G4: 45974 | H4: S/ | I4: 27
A5: 77100486 | B5: TREND BUSINESS S.A.C. | C5: IQUITOS | D5: ALVAN ESCOBEDO ROSA DEL CARMEN | E5: COUNTER | F5: 45903 | G5: 45974 | H5: S/ | I5: 27
A6: 43347817 | B6: TREND BUSINES S.A.C. | C6: IQUITOS | D6: SIAS MELENDEZ ROBIN | E6: PRODUCCIÓN / COCINA | F6: 45627 | G6: 45974 | H6: S/ | I6: 106.5
A7: 62814712 | B7: TREND BUSINES S.A.C. | C7: IQUITOS | D7: PACAYA CHOTA MAYCOL | E7: PRODUCCIÓN / COCINA | F7: 45733 | G7: 45974 | H7: S/ | I7: 106.5
A8: 74415806 | B8: TREND BUSINESS S.A.C. | C8: IQUITOS | D8: FLORES SAQUIRAY MOISES | E8: PRODUCCIÓN / COCINA | F8: 45824 | G8: 45974 | H8: S/ | I8: 106.5
A9: 62814713 | B9: TREND BUSINESS S.A.C. | C9: IQUITOS | D9: PACAYA CHOTA MARCIAL | E9: PRODUCCIÓN / COCINA | F9: 45908 | G9: 45974 | H9: S/ | I9: 106.5
A10: 42792686 | B10: VILLA INVEST S.A.C. | C10: IQUITOS | D10: BARDALES PASMIÑO DANNY AGUSTIN | E10: PRODUCCIÓN / COCINA | F10: 45505 | G10: 45974 | H10: S/ | I10: 106.5
A11: 42949350 | B11: TREND BUSINES S.A.C. | C11: IQUITOS | D11: PANDURO VELA MARCO ANTONIO | E11: PRODUCCIÓN / COCINA | F11: 45661 | G11: 45974 | H11: S/ | I11: 106.5
A12: 43446883 | B12: TREND BUSINES S.A.C. | C12: IQUITOS | D12: TORRES REATEGUI RICHARD JACKSON | E12: MOTORIZADO | F12: 45792 | G12: 45974 | H12: S/ | I12: 27
A13: 45038713 | B13: TREND BUSINES S.A.C. | C13: IQUITOS | D13: COTRINA CARDENAS MARIO GERMAN | E13: STAFF ADMINISTRATIVO | F13: 45616 | G13: 45974 | H13: S/ | I13: 30
... A68: 46831171 | B68: VILLA CHICKEN S.A.C. | C68: VCH-ADM | D68: SANCHEZ LLOCLLA ROGER YAISON | E68: BAR | F68: 45474 | G68: 46010 | H68: S/ | I68: 87

Sheet Movimientos
A1: Fecha | B1: Tipo | C1: LOCAL | D1: GRUPO | E1: CARGO ESTANDAR | F1: MATERIAL | G1: TALLA | H1: Doc/Ref | I1: DNI | J1: Entrada | K1: Salida | L1: Precio Unit | M1: Importe | N1: Obs | O1: Saldo (calc)
A2: 45974 | B2: SALIDA | C2: IQUITOS | D2: PATIO DE COMIDA | E2: CAJA | F2: POLO PIQUÉ CONCHE VINO, MANGA CORTA CAJA | G2: SML | I2: 74415759 | J2: 0 | K2: 2 | L2: 13.5 | M2: -27 | N2: Entrega
A3: 45974 | B3: SALIDA | C3: IQUITOS | D3: PATIO DE COMIDA | E3: COUNTER | F3: POLO PIQUÉ CONCHE VINO, MANGA CORTA COUNTER | G3: SML | I3: 73233227 | J3: 0 | K3: 2 | L3: 13.5 | M3: -27 | N3: Entrega
A4: 45974 | B4: SALIDA | C4: IQUITOS | D4: PATIO DE COMIDA | E4: COUNTER | F4: POLO PIQUÉ CONCHE VINO, MANGA CORTA COUNTER | G4: SML | I4: 46192476 | J4: 0 | K4: 2 | L4: 13.5 | M4: -27 | N4: Entrega
A5: 45974 | B5: SALIDA | C5: IQUITOS | D5: PATIO DE COMIDA | E5: COUNTER | F5: POLO PIQUÉ CONCHE VINO, MANGA CORTA COUNTER | G5: SML | I5: 77100486 | J5: 0 | K5: 2 | L5: 13.5 | M5: -27 | N5: Entrega
A6: 45974 | B6: SALIDA | C6: IQUITOS | D6: PATIO DE COMIDA | E6: PRODUCCIÓN / COCINA | F6: CHAQUETA DRILL BLANCO | G6: SML | I6: 43347817 | J6: 0 | K6: 2 | L6: 16.25 | M6: -32.5 | N6: Entrega
A7: 45974 | B7: SALIDA | C7: IQUITOS | D7: PATIO DE COMIDA | E7: PRODUCCIÓN / COCINA | F7: PANTALÓN SAL Y PIMIENTA | G7: SML | I7: 43347817 | J7: 0 | K7: 2 | L7: 11 | M7: -22 | N7: Entrega
